Workbook

Sheet Summary
A4: Proposal for Agent/Banca Portal & Back-office Solution: commercial summary
A5: iorta TechNXT – proposal to Insurans Islam Family Takaful Sendirian Berhad – October 2026
A7: Client | C7: Insurans Islam Family Takaful Sendirian Berhad
A8: Bidder | C8: iorta TechNXT
A9: Solution | C9: SalesVerse 2.0, configured as the IIFT Agent/Banca Portal & Back-office
A10: Currency | C10: Brunei Dollar (B$); USD indicative
A11: Indicative FX (B$ per USD 1) | C11: 1.3
A12: Quotation validity | C12: 90 days from submission
A14: 1. Commercial options at a glance (B$)
A15: Item | B15: Option A: on-premise perpetual licence | C15: Option B: subscription, iorta-hosted cloud | D15: Option C: source code handover (add-on) | E15: Notes
A16: One-time iorta fees | B16: ='Option A'!$F$14 | C16: ='Option B'!$F$15 | D16: ='Option C'!$D$8 | E16: A: licence + services; B: services + cloud set-up; C: source code + knowledge transfer
A17: Recurring iorta fees, Year 1 | B17: ='Option A'!$F$33 | C17: ='Option B'!$G$19+'Option B'!$E$29 | D17: ='Option C'!$D$44 | E17: A: AMC; B: subscription + managed services; C: support choice 2 in place of the AMC
A18: Recurring iorta fees, Years 1–5 | B18: ='Option A'!$F$38 | C18: ='Option B'!$G$24+'Option B'!$E$34 | D18: ='Option C'!$D$49 | E18: +5% a year (capped)
A19: iorta fees, five years | B19: =B16+B18 | C19: =C16+C18
A20: OPE estimate, core onsite phases (disbursements at cost) | B20: =OPE!$L$25 | C20: =OPE!$L$25 | D20: =OPE!$L$26 | E20: C: optional onsite knowledge transfer
A21: Cloud infrastructure at cost, estimate (project + five years) | B21: 0 | C21: ='Option B'!$E$49 | E21: Disbursement at cost without mark-up, or paid by IIFT directly
A22: Five-year total (B$) | B22: =B19+B20+B21 | C22: =C19+C20+C21 | E22: Excludes infrastructure procured by IIFT and third-party charges (BOM)
A23: Five-year total (USD, indicative) | B23: =ROUND(B22/Summary!$C$11,0) | C23: =ROUND(C22/Summary!$C$11,0)
A24: Infrastructure procured by IIFT (Option A, indicative one-time, not included above) | B24: B$ 20,500–42,000 | C24: – | E24: See the Bill of Materials workbook
A26: 2. Cash view by contract year (B$)
A27: Period | B27: A: iorta fees | C27: A: OPE | D27: A: total | E27: B: iorta fees | F27: B: cloud at cost | G27: B: OPE | H27: B: total
A28: Year 0 (implementation, weeks 1–28) | B28: ='Option A'!$F$14 | C28: =OPE!$L$25 | D28: =B28+C28 | E28: ='Option B'!$F$15 | F28: ='Option B'!$E$48 | G28: =OPE!$L$25 | H28: =E28+F28+G28
A29: Year 1 | B29: ='Option A'!$F$33 | C29: 0 | D29: =B29+C29 | E29: ='Option B'!$G$19+'Option B'!$E$29 | F29: ='Option B'!$E$47 | G29: 0 | H29: =E29+F29+G29
A30: Year 2 | B30: ='Option A'!$F$34 | C30: 0 | D30: =B30+C30 | E30: ='Option B'!$G$20+'Option B'!$E$30 | F30: ='Option B'!$E$47 | G30: 0 | H30: =E30+F30+G30
A31: Year 3 | B31: ='Option A'!$F$35 | C31: 0 | D31: =B31+C31 | E31: ='Option B'!$G$21+'Option B'!$E$31 | F31: ='Option B'!$E$47 | G31: 0 | H31: =E31+F31+G31
A32: Year 4 | B32: ='Option A'!$F$36 | C32: 0 | D32: =B32+C32 | E32: ='Option B'!$G$22+'Option B'!$E$32 | F32: ='Option B'!$E$47 | G32: 0 | H32: =E32+F32+G32
A33: Year 5 | B33: ='Option A'!$F$37 | C33: 0 | D33: =B33+C33 | E33: ='Option B'!$G$23+'Option B'!$E$33 | F33: ='Option B'!$E$47 | G33: 0 | H33: =E33+F33+G33
A34: Total | B34: =SUM(B28:B33) | C34: =SUM(C28:C33) | D34: =SUM(D28:D33) | E34: =SUM(E28:E33) | F34: =SUM(F28:F33) | G34: =SUM(G28:G33) | H34: =SUM(H28:H33)
A36: 3. Fee basis
A37: • WHT: inclusive. Where Brunei law requires IIFT to withhold tax from iorta's fees, IIFT deducts and remits it; iorta bears the tax and invoices are not grossed up.
A38: • Cloud infrastructure (Option B) and OPE are recharged at cost as disbursements with the provider and travel invoices attached, outside the fees to which WHT applies. IIFT may instead hold the cloud account in its own name and pay the provider directly.
A39: • OPE: exclusive. Recharged at cost for the onsite phases (OPE sheet); per diem fixed at USD 50 a day; not more than 10% above the estimate without IIFT's approval.
A40: • Third-party charges and infrastructure: exclusive. Listed in the Bill of Materials; paid by IIFT or passed through at cost without mark-up.
A41: • Recurring fees (AMC, subscription, managed services, rate card) rise by 5% a year, capped at 5% (COM-18).
A42: • No GST or VAT applies in Brunei Darussalam at present; any indirect tax introduced by law is added at the statutory rate.
A43: • Recommended: Option A (data stays in Brunei; lowest five-year cost). Option B for a lower upfront payment; convertible to Option A during the term.

Sheet Client format
A1: Fees in IIFT's requested format (Description | Fee | WHT | OPE | Total)
A2: iorta TechNXT – proposal to Insurans Islam Family Takaful Sendirian Berhad – October 2026
A4: All fees are inclusive of WHT, exclusive of OPE (recharged at cost as disbursements; estimate shown) and exclusive of third-party charges and infrastructure (Bill of Materials). USD indicative at the rate on the Summary sheet.
A6: Option A – On-premise perpetual licence
A7: Description | B7: Fee (B$) | C7: Fee (USD) | D7: WHT | E7: OPE | F7: Total (B$) | G7: Total (USD)
A8: One-time fees (licence and services)
A9: Agent/Banca Portal | B9: ='Option A'!$D$14 | C9: =ROUND(B9/Summary!$C$11,0) | D9: Inclusive | E9: Excluded | F9: =B9 | G9: =ROUND(F9/Summary!$C$11,0)
A10: Back-office solution | B10: ='Option A'!$E$14 | C10: =ROUND(B10/Summary!$C$11,0) | D10: Inclusive | E10: Excluded | F10: =B10 | G10: =ROUND(F10/Summary!$C$11,0)
A11: Total one-time fees | B11: =B9+B10 | C11: =ROUND(B11/Summary!$C$11,0) | D11: Inclusive | E11: Excluded | F11: =F9+F10 | G11: =ROUND(F11/Summary!$C$11,0)
A12: Annual maintenance (AMC), Year 1 – 22% of licence and customisation, +5% a year
A13: Agent/Banca Portal | B13: ='Option A'!$D$33 | C13: =ROUND(B13/Summary!$C$11,0) | D13: Inclusive | E13: Excluded | F13: =B13 | G13: =ROUND(F13/Summary!$C$11,0)
A14: Back-office solution | B14: ='Option A'!$E$33 | C14: =ROUND(B14/Summary!$C$11,0) | D14: Inclusive | E14: Excluded | F14: =B14 | G14: =ROUND(F14/Summary!$C$11,0)
A15: Total AMC, Year 1 | B15: =B13+B14 | C15: =ROUND(B15/Summary!$C$11,0) | D15: Inclusive | E15: Excluded | F15: =F13+F14 | G15: =ROUND(F15/Summary!$C$11,0)
A16: Out-of-pocket expenses – disbursements at cost
A17: OPE estimate for the onsite phases (travel, accommodation, per diem, insurance, transfers, visas) | D17: – | E17: =OPE!$L$25 | F17: =E17 | G17: =ROUND(F17/Summary!$C$11,0)
A19: Option B – Subscription, hosted and managed by iorta
A20: Description | B20: Fee (B$) | C20: Fee (USD) | D20: WHT | E20: OPE | F20: Total (B$) | G20: Total (USD)
A21: One-time fees (services)
A22: Agent/Banca Portal | B22: ='Option B'!$D$13 | C22: =ROUND(B22/Summary!$C$11,0) | D22: Inclusive | E22: Excluded | F22: =B22 | G22: =ROUND(F22/Summary!$C$11,0)
A23: Back-office solution | B23: ='Option B'!$E$13 | C23: =ROUND(B23/Summary!$C$11,0) | D23: Inclusive | E23: Excluded | F23: =B23 | G23: =ROUND(F23/Summary!$C$11,0)
A24: Cloud set-up, platform (landing zone, environments, monitoring, backups, DR) | B24: ='Option B'!$F$14 | C24: =ROUND(B24/Summary!$C$11,0) | D24: Inclusive | E24: Excluded | F24: =B24 | G24: =ROUND(F24/Summary!$C$11,0)
A25: Total one-time fees | B25: =B22+B23+B24 | C25: =ROUND(B25/Summary!$C$11,0) | D25: Inclusive | E25: Excluded | F25: =F22+F23+F24 | G25: =ROUND(F25/Summary!$C$11,0)
A26: Recurring fees, Year 1 – +5% a year
A27: Agent/Banca Portal subscription (B$ 1,850 a month) | B27: ='Option B'!$D$19*12 | C27: =ROUND(B27/Summary!$C$11,0) | D27: Inclusive | E27: Excluded | F27: =B27 | G27: =ROUND(F27/Summary!$C$11,0)
A28: Back-office solution subscription (B$ 1,550 a month) | B28: ='Option B'!$E$19*12 | C28: =ROUND(B28/Summary!$C$11,0) | D28: Inclusive | E28: Excluded | F28: =B28 | G28: =ROUND(F28/Summary!$C$11,0)
A29: Managed services, platform (B$ 1,100 a month) | B29: ='Option B'!$E$29 | C29: =ROUND(B29/Summary!$C$11,0) | D29: Inclusive | E29: Excluded | F29: =B29 | G29: =ROUND(F29/Summary!$C$11,0)
A30: Total recurring fees, Year 1 | B30: =B27+B28+B29 | C30: =ROUND(B30/Summary!$C$11,0) | D30: Inclusive | E30: Excluded | F30: =F27+F28+F29 | G30: =ROUND(F30/Summary!$C$11,0)
A31: Out-of-pocket expenses – disbursements at cost
A32: OPE estimate for the onsite phases (travel, accommodation, per diem, insurance, transfers, visas) | D32: – | E32: =OPE!$L$25 | F32: =E32 | G32: =ROUND(F32/Summary!$C$11,0)
A34: Cloud infrastructure (Option B) is excluded and recharged at cost as a disbursement (or paid by IIFT directly): estimate B$ 1,330 a month plus B$ 1,500 for project environments (Option B sheet). Option C (source code handover) is on its own sheet.

Sheet Option A
A1: Option A – On-premise perpetual licence: licence, implementation and annual maintenance
A2: iorta TechNXT – proposal to Insurans Islam Family Takaful Sendirian Berhad – October 2026
A4: 1. One-time fees (RFP section 10 numbering)
A5: No | B5: Component | C5: Basis | D5: Agent/Banca Portal (B$) | E5: Back-office (B$) | F5: Total (B$) | G5: In AMC base | H5: Scope
A6: 1 | B6: SalesVerse 2.0 software licence (Agent/Banca Portal and Back-office) | C6: One-off, perpetual | D6: 32500 | E6: 27500 | F6: =D6+E6 | G6: Yes | H6: Perpetual, non-exclusive, non-transferable enterprise licence for IIFT. Unlimited named users; production, DR and non-production environments included. Option A only.
A7: 2 | B7: Implementation and customisation (project management, business analysis, design, configuration, customisation, deployment) | C7: One-off | D7: 36000 | E7: 28000 | F7: =D7+E7 | G7: Yes | H7: Fixed price for the functional scope in RFP section 4 and Appendix 3, configured for IIFT's seven products, workflows, documents and reports.
A8: 3 | B8: Integration (per interface; see integration breakdown) | C8: Per interface | D8: 17500 | E8: 13000 | F8: =D8+E8 | G8: Yes | H8: Core system, FIN, AML screening, LDAP/AD, SMS gateway and Email/SMTP.
A9: 4 | B9: Data migration | C9: One-off | D9: 3000 | E9: 4500 | F9: =D9+E9 | G9: No | H9: Extraction support, transformation, cleansing, two dry runs, load and reconciliation of agreed agent, agency, bank and participant data.
A10: 7 | B10: Security (independent VAPT and re-test) | C10: One-off | D10: 4500 | E10: 4000 | F10: =D10+E10 | G10: No | H10: Independent vulnerability assessment and penetration test before go-live, remediation and re-test.
A11: 8 | B11: Testing (SIT, performance, regression, UAT support) | C11: One-off | D11: 5500 | E11: 4500 | F11: =D11+E11 | G11: No | H11: Test strategy, SIT cases and execution, performance test, automated regression suite, UAT support and defect fixing.
A12: 9 | B12: Training | C12: One-off | D12: 2500 | E12: 2000 | F12: =D12+E12 | G12: No | H12: End-user, administrator and technical training including materials.
A13: 10 | B13: Documentation | C13: One-off | D13: 2500 | E13: 2500 | F13: =D13+E13 | G13: No | H13: User, administrator, technical and operations manuals; maintained throughout the contract.
B14: Total one-time fees, Option A | D14: =SUM(D6:D13) | E14: =SUM(E6:E13) | F14: =SUM(F6:F13) | H14: Fixed price; inclusive of WHT; exclusive of OPE and third-party charges
B15: of which licence (item 1) | D15: ='Option A'!$D$6 | E15: ='Option A'!$E$6 | F15: ='Option A'!$F$6 | H15: Paid against licence milestones L1–L3
B16: of which services (items 2–10) | D16: =D14-D15 | E16: =E14-E15 | F16: =F14-F15 | H16: Paid against service milestones M1–M7; same under Option B
A18: 2. Integration per interface (item 3, COM-05)
A19: No | B19: Interface | C19: Basis | D19: Agent/Banca Portal (B$) | E19: Back-office (B$) | F19: Total (B$) | H19: Scope
A20: 3.1 | B20: Core system | C20: Per interface | D20: 4250 | E20: 4250 | F20: =D20+E20 | H20: Agent, agency, bank and policy master synchronisation; agent information exchange
A21: 3.2 | B21: Financial system (FIN) | C21: Per interface | D21: 4250 | E21: 4250 | F21: =D21+E21 | H21: End-of-day postings, receipts, commission / referral fee information, BRR reconciliation
A22: 3.3 | B22: AML screening service | C22: Per interface | D22: 2500 | E22: 2500 | F22: =D22+E22 | H22: Participant and agent screening, result capture, re-screening
A23: 3.4 | B23: LDAP / Active Directory | C23: Per interface | D23: 2000 | E23: 2000 | F23: =D23+E23 | H23: Single sign-on for back-office users; optional directory look-up for portal administration
A24: 3.5 | B24: SMS gateway | C24: Per interface | D24: 2500 | E24: 0 | F24: =D24+E24 | H24: OTP and alert delivery through IIFT-approved SMS provider
A25: 3.6 | B25: Email / SMTP relay | C25: Per interface | D25: 2000 | E25: 0 | F25: =D25+E25 | H25: Notification and document e-mail delivery through IIFT mail relay
B26: Total integration (agrees with item 3) | D26: =SUM(D20:D25) | E26: =SUM(E20:E25) | F26: =SUM(F20:F25)
A28: 3. Annual maintenance charge (AMC): 22% of licence and customisation, +5% a year
B29: AMC base: licence, implementation and integration (items flagged Yes) | D29: =D6+D7+D8 | E29: =E6+E7+E8 | F29: =F6+F7+F8 | H29: Items 1, 2 and 3
B30: AMC rate | F30: 0.22 | H30: Applied to the AMC base
B31: Yearly increase (capped, COM-18) | F31: 0.05 | H31: Years 2–5 are escalated from Year 1 and rounded to the nearest B$
A32: Year | B32: Focus (RFP section 9) | C32: Basis | D32: Agent/Banca Portal (B$) | E32: Back-office (B$) | F32: AMC (B$) | G32: Per quarter (B$) | H32: Activities
A33: Year 1 | B33: Stabilisation & Hypercare | C33: Annual | D33: =ROUND(D29*$F$30,0) | E33: =ROUND(E29*$F$30,0) | F33: =D33+E33 | G33: =F33/4 | H33: Intensive post-go-live support, defect resolution, performance tuning, monitoring and stabilisation of integrations. Includes the 6-month defect warranty.
A34: Year 2 | B34: Operational Support | C34: Annual | D34: 19866 | E34: 15824 | F34: =D34+E34 | G34: =F34/4 | H34: BAU incident management, preventive maintenance, security patches, performance monitoring and minor enhancements.
A35: Year 3 | B35: Optimisation | C35: Annual | D35: 20859 | E35: 16615 | F35: =D35+E35 | G35: =F35/4 | H35: System optimisation, reporting improvements, integration improvements and technology review.
A36: Year 4 | B36: Technology Refresh | C36: Annual | D36: 21902 | E36: 17445 | F36: =D36+E36 | G36: =F36/4 | H36: Platform compatibility review, security hardening, version upgrades and capacity assessment.
A37: Year 5 | B37: Sustainability & Transition | C37: Annual | D37: 22997 | E37: 18318 | F37: =D37+E37 | G37: =F37/4 | H37: Comprehensive health assessment, documentation refresh, knowledge transfer, technology roadmap and exit/renewal preparation.
A38: Total | B38: Five years | D38: =SUM(D33:D37) | E38: =SUM(E33:E37) | F38: =SUM(F33:F37)
A40: AMC inclusions
A41: • Helpdesk during IIFT business hours with 24x7 coverage for P1 (Critical) incidents
A42: • Incident, problem and service request management against the agreed SLA
A43: • Corrective and preventive maintenance; defect fixing
A44: • Security patches, dependency updates and vulnerability remediation
...

Sheet Option B
A1: Option B – Subscription, hosted and managed by iorta: implementation, subscription, managed services and cloud at actuals
A2: iorta TechNXT – proposal to Insurans Islam Family Takaful Sendirian Berhad – October 2026
A4: 1. Implementation fee (same scope and fees as Option A items 2–10)
A5: No | B5: Component | C5: Basis | D5: Agent/Banca Portal (B$) | E5: Back-office (B$) | F5: Total (B$) | H5: Scope
A6: 2 | B6: Implementation and customisation (project management, business analysis, design, configuration, customisation, deployment) | C6: One-off | D6: 36000 | E6: 28000 | F6: =D6+E6 | H6: Fixed price for the functional scope in RFP section 4 and Appendix 3, configured for IIFT's seven products, workflows, documents and reports.
A7: 3 | B7: Integration (per interface; see integration breakdown) | C7: Per interface | D7: 17500 | E7: 13000 | F7: =D7+E7 | H7: Core system, FIN, AML screening, LDAP/AD, SMS gateway and Email/SMTP.
A8: 4 | B8: Data migration | C8: One-off | D8: 3000 | E8: 4500 | F8: =D8+E8 | H8: Extraction support, transformation, cleansing, two dry runs, load and reconciliation of agreed agent, agency, bank and participant data.
A9: 7 | B9: Security (independent VAPT and re-test) | C9: One-off | D9: 4500 | E9: 4000 | F9: =D9+E9 | H9: Independent vulnerability assessment and penetration test before go-live, remediation and re-test.
A10: 8 | B10: Testing (SIT, performance, regression, UAT support) | C10: One-off | D10: 5500 | E10: 4500 | F10: =D10+E10 | H10: Test strategy, SIT cases and execution, performance test, automated regression suite, UAT support and defect fixing.
A11: 9 | B11: Training | C11: One-off | D11: 2500 | E11: 2000 | F11: =D11+E11 | H11: End-user, administrator and technical training including materials.
A12: 10 | B12: Documentation | C12: One-off | D12: 2500 | E12: 2500 | F12: =D12+E12 | H12: User, administrator, technical and operations manuals; maintained throughout the contract.
B13: Total implementation fee, Option B | D13: =SUM(D6:D12) | E13: =SUM(E6:E12) | F13: =SUM(F6:F12) | H13: Paid against service milestones M1–M7
A14: 5 | B14: Cloud set-up: landing zone, PROD/DR/UAT environments, monitoring, backups, DR | C14: One-off | F14: 15000 | H14: RFP item 5 (one-off part); payable at contract signing; not part of the AMC base
B15: Total one-time fees, Option B | F15: =F13+F14 | H15: Inclusive of WHT; exclusive of OPE, cloud infrastructure and third-party charges
A17: 2. Subscription (+5% a year; minimum term 60 months from go-live)
A18: Year | B18: Item | C18: Basis | D18: Portal per month (B$) | E18: Back-office per month (B$) | F18: Total per month (B$) | G18: Per year (B$) | H18: Notes
A19: Year 1 | B19: Subscription: right to use, maintenance and support, application management | C19: Monthly in advance | D19: 1850 | E19: 1550 | F19: =D19+E19 | G19: =F19*12 | H19: Year 1 rates as quoted; later years escalated by 5% and rounded to the nearest B$
A20: Year 2 | B20: Subscription: right to use, maintenance and support, application management | C20: Monthly in advance | D20: 1943 | E20: 1628 | F20: =D20+E20 | G20: =F20*12
A21: Year 3 | B21: Subscription: right to use, maintenance and support, application management | C21: Monthly in advance | D21: 2040 | E21: 1709 | F21: =D21+E21 | G21: =F21*12
A22: Year 4 | B22: Subscription: right to use, maintenance and support, application management | C22: Monthly in advance | D22: 2142 | E22: 1794 | F22: =D22+E22 | G22: =F22*12
A23: Year 5 | B23: Subscription: right to use, maintenance and support, application management | C23: Monthly in advance | D23: 2249 | E23: 1884 | F23: =D23+E23 | G23: =F23*12
A24: Total | B24: Five years | G24: =SUM(G19:G23)
B25: Minimum term value (60 months) | G25: =SUM(G19:G23) | H25: Payable if IIFT ends the subscription early other than for iorta's breach
A27: 3. Managed services by iorta (+5% a year)
A28: Year | B28: Item | C28: Basis | D28: Per month (B$) | E28: Per year (B$) | F28: Inclusions
A29: Year 1 | B29: Managed services: cloud operations, monitoring, patching, backups, DR, security | C29: Monthly in advance | D29: 1100 | E29: =D29*12 | F29: 24x7 infrastructure and availability monitoring with alerting
A30: Year 2 | B30: Managed services: cloud operations, monitoring, patching, backups, DR, security | C30: Monthly in advance | D30: 1155 | E30: =D30*12 | F30: Operating system, container and database patching in agreed windows
A31: Year 3 | B31: Managed services: cloud operations, monitoring, patching, backups, DR, security | C31: Monthly in advance | D31: 1213 | E31: =D31*12 | F31: Backups, monthly restore tests and the annual DR drill
A32: Year 4 | B32: Managed services: cloud operations, monitoring, patching, backups, DR, security | C32: Monthly in advance | D32: 1273 | E32: =D32*12 | F32: Security monitoring: WAF, threat detection, vulnerability scanning of the cloud estate
A33: Year 5 | B33: Managed services: cloud operations, monitoring, patching, backups, DR, security | C33: Monthly in advance | D33: 1337 | E33: =D33*12 | F33: Capacity, performance and cloud cost management with a monthly report
A34: Total | B34: Five years | E34: =SUM(E29:E33) | F34: Infrastructure incident response and liaison with the cloud provider
A36: 4. Cloud infrastructure recharged at cost (disbursement) – estimate (AWS Asia Pacific (Malaysia) or Azure Malaysia West)
A37: No | B37: Service | C37: Billing basis | D37: B$ per month | E37: B$ per year | F37: Reference sizing
A38: 1 | B38: Container compute, 2 tasks across 2 availability zones (Portal, back-office and API) | C38: At cost (disbursement) | D38: 260 | E38: =D38*12 | F38: 2 tasks × (1 vCPU, 2 GB) incl. ClamAV sidecar; scales to 4 tasks
A39: 2 | B39: Managed PostgreSQL, Multi-AZ, 100 GB, automated backups (Database and point-in-time recovery) | C39: At cost (disbursement) | D39: 420 | E39: =D39*12 | F39: db.t4g.large (2 vCPU, 8 GB), Multi-AZ, 100 GB gp3, 35-day backups and PITR
A40: 3 | B40: Application load balancer and web application firewall (TLS termination, OWASP rules) | C40: At cost (disbursement) | D40: 130 | E40: =D40*12 | F40: 1 load balancer; WAF with managed OWASP rule sets; managed TLS certificate
A41: 4 | B41: NAT gateway and data transfer (Outbound integration and updates) | C41: At cost (disbursement) | D41: 90 | E41: =D41*12 | F41: NAT gateway, site-to-site VPN to the IITH data centre, outbound data
A42: 5 | B42: Object storage (encrypted) and cross-region backup copies (Documents, backups, DR copies) | C42: At cost (disbursement) | D42: 70 | E42: =D42*12 | F42: Shared file storage up to 100 GB; about 200 GB object storage; cross-region copy
A43: 6 | B43: Logging, metrics, alarms and threat detection (Monitoring and security) | C43: At cost (disbursement) | D43: 70 | E43: =D43*12 | F43: Log retention 90 days, metrics, alarms, threat detection
A44: 7 | B44: Secrets and key management (Credentials and encryption keys) | C44: At cost (disbursement) | D44: 20 | E44: =D44*12 | F44: Secrets store and customer-managed encryption keys
...

Sheet Option C
A1: Option C – Source code handover (add-on): core source code with knowledge transfer and transition
A2: iorta TechNXT – proposal to Insurans Islam Family Takaful Sendirian Berhad – October 2026
A4: 1. Price
B5: Component | C5: Basis | D5: Amount (B$) | E5: Amount (USD) | F5: Notes
B6: Source code licence (SalesVerse 2.0 core platform) | C6: One-off | D6: 60000 | E6: =ROUND(D6/Summary!$C$11,0) | F6: Use, modify and maintain for IIFT and IITH group internal use; no resale
B7: Knowledge transfer and transition (8 weeks) | C7: One-off | D7: 28000 | E7: =ROUND(D7/Summary!$C$11,0) | F7: After go-live and hypercare exit
B8: Total Option C | D8: =D6+D7 | E8: =ROUND(D8/Summary!$C$11,0) | F8: Exclusive of OPE (onsite weeks at actuals)
B9: OPE for onsite knowledge transfer (estimate) | C9: At cost (disbursement) | D9: =OPE!$L$26 | E9: =ROUND(D9/Summary!$C$11,0) | F9: Solution Architect and Senior Developer onsite for the walkthrough weeks
A10: Price held if Option C is exercised within 12 months of go-live; later exercise adds 5% for each further contract year.
A12: 2. Payment milestones
A13: Code | B13: Payment trigger | C13: Component | D13: Share | E13: Amount (B$)
A14: C1 | B14: Delivery of the source code repository and a verified build by IIFT | C14: Source code licence | D14: 1 | E14: =ROUND(D14*$D$6,0)
A15: C2 | B15: Start of knowledge transfer | C15: Knowledge transfer | D15: 0.5 | E15: =ROUND(D15*$D$7,0)
A16: C3 | B16: Handover certificate signed | C16: Knowledge transfer | D16: 0.5 | E16: =ROUND(D16*$D$7,0)
B17: Total | E17: =SUM(E14:E16)
A19: 3. Knowledge transfer and transition plan
A20: Week | B20: Activity | C20: Outcome
A21: 1 | B21: Transition plan, roles, access to repositories and pipelines | C21: Signed transition plan
A22: 2 | B22: Architecture, data model and module walkthroughs | C22: Architecture walkthrough sign-off
A23: 3 | B23: Code walkthroughs: sales, policy, billing and claims modules | C23: Module checklists
A24: 4 | B24: Code walkthroughs: workflow, integration, reports, security | C24: Module checklists
A25: 5 | B25: Build, test, CI/CD, release and database migration practice | C25: IIFT team produces a release
A26: 6 | B26: Shadow support: IIFT developers observe live tickets | C26: Ticket log
A27: 7 | B27: Reverse shadow: IIFT developers resolve tickets, iorta reviews | C27: Ticket log, code reviews
A28: 8 | B28: Competency assessment, documentation handover, closure | C28: Handover certificate
A29: Acceptance: handover certificate signed when IIFT's team builds and deploys a release to SIT from the delivered repository without iorta's help, resolves tickets in the reverse-shadow weeks and receives the documentation set.
A31: 4. Deliverables
A32: • Full source code of SalesVerse 2.0 core and IIFT customisations in a Git repository with history
A33: • Build scripts, CI/CD pipeline definitions, infrastructure and container definitions
A34: • Database schema, migrations, reference data and seed scripts
A35: • Automated test suites (unit, end-to-end, security checks) and test data
A36: • Developer guide, architecture document, data dictionary, runbooks and coding standards
A37: • Third-party component inventory and software bill of materials (SBOM)
A38: Source code of IIFT-specific components (configuration, adapters, reports, templates, migration and build scripts) is delivered under every option (RFP DEL-11); Option C adds the core platform.
A40: 5. Support after handover – choice 2: platform updates and L3 support at 10% of the AMC base
B41: AMC base (Option A sheet) | D41: ='Option A'!$F$29
B42: Rate | C42: In place of the AMC | D42: 0.1
A43: Year | B43: Support after handover | C43: Basis | D43: Choice 2 (B$) | E43: Full AMC (B$) | F43: Difference (B$) | G43: Notes
A44: Year 1 | B44: Platform updates, security patches, L3 support for the core | C44: Quarterly in advance | D44: =ROUND(D41*D42,0) | E44: ='Option A'!$F$33 | F44: =E44-D44 | G44: Pro rata from the month after the handover certificate
A45: Year 2 | B45: Platform updates, security patches, L3 support for the core | C45: Quarterly in advance | D45: 16223 | E45: ='Option A'!$F$34 | F45: =E45-D45
...

Sheet RFP Section 10
A1: Commercial pricing breakdown, RFP section 10 (items 1–21), Option A and Option B
A2: iorta TechNXT – proposal to Insurans Islam Family Takaful Sendirian Berhad – October 2026
A4: No | B4: Commercial component | C4: Pricing basis | D4: A: Portal (B$) | E4: A: Back-office (B$) | F4: A: Total (B$) | G4: B: Portal (B$) | H4: B: Back-office (B$) | I4: B: Total (B$) | J4: Option A: rate / treatment | K4: Option B: rate / treatment | L4: Remarks
A5: 1 | B5: Software / application licence | C5: One-off, perpetual | D5: 32500 | E5: 27500 | F5: =D5+E5 | K5: Included in subscription | L5: Perpetual, non-exclusive, non-transferable enterprise licence for IIFT. Unlimited named users; production, DR and non-production environments included. Option A only.
A6: 2 | B6: Implementation and customisation (project management, business analysis, design, configuration, customisation, deployment) | C6: One-off | D6: 36000 | E6: 28000 | F6: =D6+E6 | G6: 36000 | H6: 28000 | I6: =G6+H6 | L6: Fixed price for the functional scope in RFP section 4 and Appendix 3, configured for IIFT's seven products, workflows, documents and reports.
A7: 3 | B7: Integration (per interface; see integration breakdown) | C7: Per interface | D7: 17500 | E7: 13000 | F7: =D7+E7 | G7: 17500 | H7: 13000 | I7: =G7+H7 | L7: Core system, FIN, AML screening, LDAP/AD, SMS gateway and Email/SMTP.
A8: 4 | B8: Data migration | C8: One-off | D8: 3000 | E8: 4500 | F8: =D8+E8 | G8: 3000 | H8: 4500 | I8: =G8+H8 | L8: Extraction support, transformation, cleansing, two dry runs, load and reconciliation of agreed agent, agency, bank and participant data.
A9: 5 | B9: Infrastructure / cloud | C9: Annual | I9: 15000 | J9: IIFT procures (BOM); B$0 from iorta | K9: Cloud set-up B$ 15,000 one-off; managed services B$ 13,200 a year (Year 1); cloud at cost ≈ B$ 15,960 a year | L9: Servers or VMs, OS, storage, network and DR site to iorta's sizing. Indicative B$ 20,500–42,000 one-time if provisioned new (IIFT's own procurement).
A10: 6 | B10: Database | C10: Annual | J10: B$0 – PostgreSQL 16, no licence fee | K10: In cloud actuals; support in managed services | L10: Open-source PostgreSQL licence. Database support is part of the AMC; optional commercial PostgreSQL support is listed in the BOM.
A11: 7 | B11: Security (independent VAPT and re-test) | C11: One-off | D11: 4500 | E11: 4000 | F11: =D11+E11 | G11: 4500 | H11: 4000 | I11: =G11+H11 | L11: Independent vulnerability assessment and penetration test before go-live, remediation and re-test.
A12: 8 | B12: Testing (SIT, performance, regression, UAT support) | C12: One-off | D12: 5500 | E12: 4500 | F12: =D12+E12 | G12: 5500 | H12: 4500 | I12: =G12+H12 | L12: Test strategy, SIT cases and execution, performance test, automated regression suite, UAT support and defect fixing.
A13: 9 | B13: Training | C13: One-off | D13: 2500 | E13: 2000 | F13: =D13+E13 | G13: 2500 | H13: 2000 | I13: =G13+H13 | L13: End-user, administrator and technical training including materials.
A14: 10 | B14: Documentation | C14: One-off | D14: 2500 | E14: 2500 | F14: =D14+E14 | G14: 2500 | H14: 2500 | I14: =G14+H14 | L14: User, administrator, technical and operations manuals; maintained throughout the contract.
A15: 11 | B15: Warranty | C15: Included | J15: Included – 6 months | K15: Included – 6 months | L15: Defect correction at no charge for 6 months from production go-live.
B16: Subtotal one-time (items 1–11) | C16: One-off | D16: =SUM(D5:D14) | E16: =SUM(E5:E14) | F16: =SUM(F5:F14) | G16: =SUM(G5:G14) | H16: =SUM(H5:H14) | I16: =SUM(I5:I14) | J16: Fixed price | K16: Fixed price; includes the cloud set-up (item 5) | L16: Inclusive of WHT; exclusive of OPE and third-party charges
A17: 12 | B17: Year 1 maintenance (AMC): Stabilisation & Hypercare | C17: Annual | D17: 18920 | E17: 15070 | F17: =D17+E17 | G17: 22200 | H17: 18600 | I17: =G17+H17 | L17: Intensive post-go-live support, defect resolution, performance tuning, monitoring and stabilisation of integrations. Includes the 6-month defect warranty. Option B: subscription for the year.
A18: 13 | B18: Year 2 maintenance (AMC): Operational Support | C18: Annual | D18: 19866 | E18: 15824 | F18: =D18+E18 | G18: 23316 | H18: 19536 | I18: =G18+H18 | L18: BAU incident management, preventive maintenance, security patches, performance monitoring and minor enhancements. Option B: subscription for the year.
A19: 14 | B19: Year 3 maintenance (AMC): Optimisation | C19: Annual | D19: 20859 | E19: 16615 | F19: =D19+E19 | G19: 24480 | H19: 20508 | I19: =G19+H19 | L19: System optimisation, reporting improvements, integration improvements and technology review. Option B: subscription for the year.
A20: 15 | B20: Year 4 maintenance (AMC): Technology Refresh | C20: Annual | D20: 21902 | E20: 17445 | F20: =D20+E20 | G20: 25704 | H20: 21528 | I20: =G20+H20 | L20: Platform compatibility review, security hardening, version upgrades and capacity assessment. Option B: subscription for the year.
A21: 16 | B21: Year 5 maintenance (AMC): Sustainability & Transition | C21: Annual | D21: 22997 | E21: 18318 | F21: =D21+E21 | G21: 26988 | H21: 22608 | I21: =G21+H21 | L21: Comprehensive health assessment, documentation refresh, knowledge transfer, technology roadmap and exit/renewal preparation. Option B: subscription for the year.
B22: Subtotal Years 1–5 (items 12–16) | C22: Annual | D22: =SUM(D17:D21) | E22: =SUM(E17:E21) | F22: =SUM(F17:F21) | G22: =SUM(G17:G21) | H22: =SUM(H17:H21) | I22: =SUM(I17:I21) | J22: AMC, +5% a year | K22: Subscription, +5% a year | L22: Managed services (item 5, Option B) are shown on the Option B sheet
A23: 17 | B23: Enhancements and change requests | C23: Per man-day / per hour | J23: B$ 680 per man-day; B$ 90 per hour | K23: B$ 680 per man-day; B$ 90 per hour | L23: Blended rate for all roles; quoted per change request after impact assessment. Rates rise 5% a year.
A24: 18 | B24: Onsite support (unplanned visits) | C24: Per day | J24: B$ 850 per day + OPE | K24: B$ 850 per day + OPE | L24: Planned onsite phases are covered by the fixed fees; only travel costs are charged as OPE. Rates rise 5% a year.
A25: 19 | B25: After-hours support | C25: Per hour / Included | J25: P1 (Critical): included; other after-hours work: B$ 120 per hour | K25: P1 (Critical): included; other after-hours work: B$ 120 per hour | L25: After-hours work other than P1 is performed only on IIFT request. Rates rise 5% a year.
A26: 20 | B26: Third-party charges | C26: Annual / usage | J26: Excluded – see Bill of Materials | K26: Excluded – see Bill of Materials | L26: SMS messages, AML data service, SSL certificates, e-mail relay: indicative B$ 600–4,720 a year, paid by IIFT or passed through at cost.
A27: 21 | B27: Exit / transition | C27: Included | J27: Included in Year 5 AMC | K27: Included in the subscription (end of term) | L27: Knowledge transfer, data extraction and technical handover at contract end. Core source code handover is Option C.
A29: Rates for items 17–19 are Year 1 rates and rise by 5% a year (Rate card sheet). Third-party charges (item 20) are detailed in the Bill of Materials workbook.

Sheet OPE
A1: Out-of-pocket expenses (OPE): onsite plan and estimate, recharged at cost as disbursements
A2: iorta TechNXT – proposal to Insurans Islam Family Takaful Sendirian Berhad – October 2026
A4: 1. Unit rates (B$)
A5: Cost item | B5: From Malaysia | C5: From India | D5: Basis
A6: Return airfare (economy) | B6: 500 | C6: 1200 | D6: Per trip, at actuals
A7: Travel insurance | B7: 50 | C7: 70 | D7: Per trip, at actuals
A8: Airport transfers | B8: 80 | C8: 80 | D8: Per trip, at actuals
A9: Visa | B9: 0 | C9: 40 | D9: Per trip, at actuals
A10: Accommodation per night | B10: 150 | C10: 150 | D10: Per night, at actuals
A11: Per diem (USD per day) | B11: 50 | C11: 50 | D11: Fixed; per day onsite including travel days
A12: Per diem (B$ per day) | B12: =ROUND(B11*Summary!$C$11,0) | C12: =ROUND(C11*Summary!$C$11,0) | D12: Converted at the indicative rate on the Summary sheet
A14: 2. Onsite plan and estimate
A15: Phase | B15: Role | C15: From | D15: Nights | E15: Days | F15: Airfare | G15: Hotel | H15: Per diem | I15: Insurance | J15: Transfers | K15: Visa | L15: Total (B$) | M15: Type
A16: Requirements gathering and fit-gap (weeks 1–4) | B16: Project Manager | C16: Malaysia | D16: 12 | E16: =D16+1 | F16: =$B$6 | G16: =D16*$B$10 | H16: =E16*$B$12 | I16: =$B$7 | J16: =$B$8 | K16: =$B$9 | L16: =SUM(F16:K16) | M16: Core
A17: Requirements gathering and fit-gap (weeks 1–4) | B17: Business Analyst | C17: Malaysia | D17: 19 | E17: =D17+1 | F17: =$B$6 | G17: =D17*$B$10 | H17: =E17*$B$12 | I17: =$B$7 | J17: =$B$8 | K17: =$B$9 | L17: =SUM(F17:K17) | M17: Core
A18: Requirements gathering and fit-gap (weeks 1–4) | B18: Solution Architect | C18: India | D18: 12 | E18: =D18+1 | F18: =$C$6 | G18: =D18*$C$10 | H18: =E18*$C$12 | I18: =$C$7 | J18: =$C$8 | K18: =$C$9 | L18: =SUM(F18:K18) | M18: Core
A19: User training and UAT support (weeks 19–23) | B19: Business Analyst / Trainer | C19: Malaysia | D19: 19 | E19: =D19+1 | F19: =$B$6 | G19: =D19*$B$10 | H19: =E19*$B$12 | I19: =$B$7 | J19: =$B$8 | K19: =$B$9 | L19: =SUM(F19:K19) | M19: Core
A20: User training and UAT support (weeks 19–23) | B20: QA Lead | C20: India | D20: 12 | E20: =D20+1 | F20: =$C$6 | G20: =D20*$C$10 | H20: =E20*$C$12 | I20: =$C$7 | J20: =$C$8 | K20: =$C$9 | L20: =SUM(F20:K20) | M20: Core
A21: Go-live and one month of support (weeks 24–28) | B21: Senior Developer | C21: India | D21: 33 | E21: =D21+1 | F21: =$C$6 | G21: =D21*$C$10 | H21: =E21*$C$12 | I21: =$C$7 | J21: =$C$8 | K21: =$C$9 | L21: =SUM(F21:K21) | M21: Core
A22: Go-live and one month of support (weeks 24–28) | B22: Project Manager | C22: Malaysia | D22: 6 | E22: =D22+1 | F22: =$B$6 | G22: =D22*$B$10 | H22: =E22*$B$12 | I22: =$B$7 | J22: =$B$8 | K22: =$B$9 | L22: =SUM(F22:K22) | M22: Core
A23: Knowledge transfer and source code handover (Option C) | B23: Solution Architect | C23: India | D23: 12 | E23: =D23+1 | F23: =$C$6 | G23: =D23*$C$10 | H23: =E23*$C$12 | I23: =$C$7 | J23: =$C$8 | K23: =$C$9 | L23: =SUM(F23:K23) | M23: Optional (Option C)
A24: Knowledge transfer and source code handover (Option C) | B24: Senior Developer | C24: India | D24: 12 | E24: =D24+1 | F24: =$C$6 | G24: =D24*$C$10 | H24: =E24*$C$12 | I24: =$C$7 | J24: =$C$8 | K24: =$C$9 | L24: =SUM(F24:K24) | M24: Optional (Option C)
A25: Core onsite phases | D25: =SUM(D16:D22) | L25: =SUM(L16:L22)
A26: Option C knowledge transfer (optional) | D26: =SUM(D23:D24) | L26: =SUM(L23:L24)
A27: Total including Option C | L27: =L25+L26
A28: Ceiling without IIFT's prior approval: estimate + 10% (core phases) | L28: =ROUND(L25*1.1,0)
A30: 3. Rules
A31: • Recharged monthly in arrears at cost as disbursements, with travel invoices and receipts attached and no mark-up, outside the fees to which WHT applies; the per diem is fixed and needs no receipts.
A32: • Total OPE will not exceed the estimate by more than 10% without IIFT's prior written approval.
A33: • Economy-class flights; business hotels near IIFT's office. Accommodation or transport provided by IIFT reduces the OPE.
A34: • Trips agreed with IIFT's project manager two weeks ahead; all other work is remote from Malaysia and India.
A35: • Extra onsite days requested by IIFT outside these phases: rate card (B$ 850 a day in Year 1) plus OPE.

Sheet Rate card
A1: Rate card (RFP section 10 items 17–19 and 21; COM-16), +5% a year
A2: iorta TechNXT – proposal to Insurans Islam Family Takaful Sendirian Berhad – October 2026
A4: Service | B4: Unit | C4: Year 1 (B$) | D4: Year 2 (B$) | E4: Year 3 (B$) | F4: Year 4 (B$) | G4: Year 5 (B$) | H4: Notes
A5: Enhancements and change requests | B5: Per man-day | C5: 680 | D5: 714 | E5: 750 | F5: 787 | G5: 827 | H5: Blended rate, all roles; 60 hours a year included in AMC / subscription
A6: Enhancements and change requests | B6: Per hour | C6: 90 | D6: 95 | E6: 99 | F6: 104 | G6: 109 | H6: Blended rate, all roles
A7: Onsite support, unplanned visit | B7: Per day | C7: 850 | D7: 893 | E7: 937 | F7: 984 | G7: 1033 | H7: Plus OPE at actuals
A8: After-hours support other than P1 | B8: Per hour | C8: 120 | D8: 126 | E8: 132 | F8: 139 | G8: 146 | H8: Only at IIFT's request
A9: After-hours support for P1 (Critical) incidents | B9: Per incident | C9: Included | D9: Included | E9: Included | F9: Included | G9: Included | H9: 24x7
A10: Exit and transition at contract end | B10: Fixed | C10: Included | D10: Included | E10: Included | F10: Included | G10: Included | H10: Included in Year 5 AMC or at the end of the subscription
A12: Change requests: written request, impact assessment within five business days, quotation at these rates, written approval before work starts. Quotations remain valid for 90 days.

Sheet Payment schedules
A1: Payment schedules (invoices payable within 30 days)
A2: iorta TechNXT – proposal to Insurans Islam Family Takaful Sendirian Berhad – October 2026
A4: 1. Option A licence fee
A5: Milestone | B5: Payment trigger | C5: Target | D5: Share | E5: Amount (B$) | F5: Amount (USD) | G5: Notes
A6: L1 | B6: Contract signing | C6: Signature | D6: 0.5 | E6: =ROUND(D6*'Option A'!$F$6,0) | F6: =ROUND(E6/Summary!$C$11,0)
A7: L2 | B7: Installation in the SIT environment | C7: About week 8 | D7: 0.3 | E7: =ROUND(D7*'Option A'!$F$6,0) | F7: =ROUND(E7/Summary!$C$11,0)
A8: L3 | B8: Production go-live | C8: Week 24 | D8: 0.2 | E8: =ROUND(D8*'Option A'!$F$6,0) | F8: =ROUND(E8/Summary!$C$11,0)
B9: Total licence fee | D9: =SUM(D6:D8) | E9: =SUM(E6:E8) | F9: =ROUND(E9/Summary!$C$11,0)
A11: 2. Services fee (Options A and B)
A12: Milestone | B12: Payment trigger | C12: Target | D12: Share | E12: Amount (B$) | F12: Amount (USD) | G12: Notes
A13: M1 | B13: Contract signing and project kick-off | C13: Week 2 | D13: 0.15 | E13: =ROUND(D13*'Option B'!$F$13,0) | F13: =ROUND(E13/Summary!$C$11,0)
A14: M2 | B14: Design sign-off (BRS, FRS, SAD, TDD, UI/UX, interface specification) | C14: Week 6 | D14: 0.15 | E14: =ROUND(D14*'Option B'!$F$13,0) | F14: =ROUND(E14/Summary!$C$11,0)
A15: M4 | B15: SIT exit and security clearance (VAPT remediated) | C15: Week 19 | D15: 0.25 | E15: =ROUND(D15*'Option B'!$F$13,0) | F15: =ROUND(E15/Summary!$C$11,0)
A16: M5 | B16: UAT sign-off | C16: Week 22 | D16: 0.25 | E16: =ROUND(D16*'Option B'!$F$13,0) | F16: =ROUND(E16/Summary!$C$11,0)
A17: M6 | B17: Production go-live | C17: Week 24 | D17: 0.15 | E17: =ROUND(D17*'Option B'!$F$13,0) | F17: =ROUND(E17/Summary!$C$11,0)
A18: M7 | B18: Hypercare exit and project closure | C18: Week 28 | D18: 0.05 | E18: =ROUND(D18*'Option B'!$F$13,0) | F18: =ROUND(E18/Summary!$C$11,0)
B19: Total services fee | D19: =SUM(D13:D18) | E19: =SUM(E13:E18) | F19: =ROUND(E19/Summary!$C$11,0) | G19: M3 (build complete, week 16) carries no payment
A21: 3. Recurring charges
A22: Year | B22: Charge | C22: Option | D22: Per invoice (B$) | E22: Per year (B$) | F22: Billing
A23: Year 1 | B23: Annual maintenance (AMC) | C23: A | D23: ='Option A'!$F$33/4 | E23: ='Option A'!$F$33 | F23: Quarterly in advance from go-live
A24: Year 2 | B24: Annual maintenance (AMC) | C24: A | D24: ='Option A'!$F$34/4 | E24: ='Option A'!$F$34 | F24: Quarterly in advance from go-live
A25: Year 3 | B25: Annual maintenance (AMC) | C25: A | D25: ='Option A'!$F$35/4 | E25: ='Option A'!$F$35 | F25: Quarterly in advance from go-live
A26: Year 4 | B26: Annual maintenance (AMC) | C26: A | D26: ='Option A'!$F$36/4 | E26: ='Option A'!$F$36 | F26: Quarterly in advance from go-live
A27: Year 5 | B27: Annual maintenance (AMC) | C27: A | D27: ='Option A'!$F$37/4 | E27: ='Option A'!$F$37 | F27: Quarterly in advance from go-live
A28: Year 1 | B28: Subscription | C28: B | D28: ='Option B'!$F$19 | E28: ='Option B'!$G$19 | F28: Monthly in advance from go-live
A29: Year 2 | B29: Subscription | C29: B | D29: ='Option B'!$F$20 | E29: ='Option B'!$G$20 | F29: Monthly in advance from go-live
A30: Year 3 | B30: Subscription | C30: B | D30: ='Option B'!$F$21 | E30: ='Option B'!$G$21 | F30: Monthly in advance from go-live
A31: Year 4 | B31: Subscription | C31: B | D31: ='Option B'!$F$22 | E31: ='Option B'!$G$22 | F31: Monthly in advance from go-live
A32: Year 5 | B32: Subscription | C32: B | D32: ='Option B'!$F$23 | E32: ='Option B'!$G$23 | F32: Monthly in advance from go-live
A33: Year 1 | B33: Managed services | C33: B | D33: ='Option B'!$D$29 | E33: ='Option B'!$E$29 | F33: Monthly in advance from go-live
A34: Year 2 | B34: Managed services | C34: B | D34: ='Option B'!$D$30 | E34: ='Option B'!$E$30 | F34: Monthly in advance from go-live
A35: Year 3 | B35: Managed services | C35: B | D35: ='Option B'!$D$31 | E35: ='Option B'!$E$31 | F35: Monthly in advance from go-live
A36: Year 4 | B36: Managed services | C36: B | D36: ='Option B'!$D$32 | E36: ='Option B'!$E$32 | F36: Monthly in advance from go-live
A37: Year 5 | B37: Managed services | C37: B | D37: ='Option B'!$D$33 | E37: ='Option B'!$E$33 | F37: Monthly in advance from go-live
A38: At signing | B38: Cloud set-up fee | C38: B | D38: ='Option B'!$F$14 | F38: Once, at contract signing
A39: Each month | B39: Cloud infrastructure (estimate) | C39: B | D39: ='Option B'!$D$47 | E39: ='Option B'!$E$47 | F39: Monthly in arrears, disbursement at cost with provider invoices (or paid by IIFT directly)
A40: As incurred | B40: OPE | C40: A and B | F40: Monthly in arrears, disbursement at cost with travel invoices
A42: 4. Option C
A43: Milestone | B43: Payment trigger | C43: Component | D43: Share | E43: Amount (B$) | F43: Amount (USD) | G43: Notes
A44: C1 | B44: Delivery of the source code repository and a verified build by IIFT | C44: Source code licence | D44: 1 | E44: =ROUND(D44*60000,0) | F44: =ROUND(E44/Summary!$C$11,0)
...

Sheet Assumptions
A1: Commercial assumptions and exclusions
A2: iorta TechNXT – proposal to Insurans Islam Family Takaful Sendirian Berhad – October 2026
A4: # | B4: Assumption
A5: 1 | B5: Currency: Brunei Dollars. USD equivalents are indicative at USD 1 = B$ 1.30, rounded to the nearest dollar; the B$ amounts are binding.
A6: 2 | B6: Scope is the RFP (sections 3–8, Appendices 1–4) as described in the proposal; changes follow the change request process at the rate card.
A7: 3 | B7: Implementation fees are fixed prices; recurring fees follow the yearly schedule with increases capped at 5%.
A8: 4 | B8: Sizing basis: 26 named users (Appendix 1) and about 628 policies a year (Appendix 2); designed for 100 concurrent and 500 named users. Unlimited named users for IIFT under both options.
A9: 5 | B9: Option A: IIFT procures infrastructure to iorta's sizing (Bill of Materials) and provides SIT and UAT by weeks 8 and 16 and production and DR by week 20.
A10: 6 | B10: Option B: hosting in AWS Asia Pacific (Malaysia) or Azure Malaysia West; IIFT approves the region and makes the AMBD outsourcing and cloud notification; one-off cloud set-up fee B$ 15,000 payable at contract signing.
A11: 7 | B11: Cloud infrastructure and OPE are recharged at cost as disbursements with provider and travel invoices attached, outside the fees to which WHT applies; IIFT may instead hold the cloud account in its own name and pay the provider directly (iorta then operates it under the managed services).
A12: 8 | B12: Option B minimum term 60 months from go-live.
A13: 9 | B13: Option C: after go-live and hypercare; 8 weeks of knowledge transfer for up to six IIFT/IITH or nominated contractor staff; price held for exercise within 12 months of go-live.
A14: 10 | B14: Data migration: agent, agency, bank, branch, participant and reference data, below 10,000 records from no more than three source extracts.
A15: 11 | B15: OPE: onsite presence for requirements gathering, training and UAT support, go-live with one month of support and (Option C) knowledge transfer; all other work remote from Malaysia and India.
A16: 12 | B16: Use by other IITH group companies (e.g. IIGT) is priced separately.
... A18: 14 | B18: Exclusions: infrastructure (Option A), cloud charges (Option B, at cost), third-party charges, OPE, changes to IIFT's other systems, Malay translation, payment gateway, native mobile apps, post-go-live penetration tests beyond the pre-go-live VAPT and re-test.
