Workbook

Sheet Read-me
A4: SalesVerse 2.0 – Test Cases
A5: iorta TechNXT – IIFT Agent/Banca Portal & Back-office for Insurans Islam Family Takaful Sendirian Berhad – October 2026
A7: Document reference | B7: IIFT-SV2-TCS
A8: RFP deliverables | B8: DEL-13 (test scenarios and expected results), DEL-14 precursor (execution evidence); UAT cases (DEL-15) are derived from the scenarios marked UAT
A9: Status as of | B9: 2 October 2026, source commit af2fb05
A10: Companion document | B10: SalesVerse-2.0-Test-Strategy (IIFT-SV2-TST): levels, environments, entry/exit criteria, schedule; its 'Status post testing' section is built from the same data as the Summary sheet
A11: Classification | B11: Commercial-in-Confidence
A13: How to read this workbook
A14: • Scenarios: one business or technical situation per row, traced to RFP identifiers (AP, BO, INT, COM, NFR, DEL, MNT, FFR) with persona, pre-conditions and expected end state.
A15: • Conditions: the rules and decisions inside each scenario that at least one case verifies (for example 'nominee shares must total 100%').
A16: • Cases: the executable cases with numbered steps, test data, expected result, level, automation, status, evidence and execution details. Filter by Area, Level or Status.
A17: • Defects: failures found during the run with severity and status (headers only when none).
A18: • Traceability: every RFP requirement in scope with its scenarios, case identifiers and coverage; requirements without a case are marked.
A19: • Execution log: every API case executed by the test run script, the automated suite re-runs and the security check run, with request, response and verdict.
A20: • Summary: counts by status, level, area and automation as formulas over the Cases sheet, with the catalogue's own count beside each for a drift check.
A22: Status and level definitions
A23: Term | B23: Meaning
A24: Passed | B24: Executed and the expected result observed (automated run, API run or manual exploratory run with a screen capture).
A25: Failed | B25: Executed and the expected result not observed; a defect reference is given.
A26: Blocked | B26: Execution attempted but a pre-condition was not available in the test data or environment.
A27: Not executed | B27: Not run in the iorta test environment; the Evidence column states why (IIFT environment, time-based job, UAT, VAPT, performance scale, not yet built).
A28: Unit | B28: Vitest unit tests of the API (business rules, rating engines, validators) and of web components (Testing Library).
A29: API | B29: System cases executed by tools/testing/api-test-run.mjs through the HTTP API of the running demonstration instance.
A30: E2E | B30: The end-to-end suite apps/api/test/*.e2e-spec.ts (supertest against a dedicated PostgreSQL test database).
A31: UI | B31: Manual exploratory runs in the browser; evidence is a screen capture in evidence/ui-screens.
A32: Security | B32: The OWASP Top 10 checks in tools/security/security-checks.mjs.
A33: SIT / Perf / UAT | B33: Levels that need IIFT's systems, scale or users; executed in weeks 16–22 of the plan.
A34: Automation | B34: 'Automated – <spec>' for tests in the repository; 'Executed – API run' for the scripted run; 'Manual (exploratory)'; 'Not automated'.
A36: Evidence files (docs/technical/evidence)
A37: File | B37: Content
A38: api-unit-tests.json | B38: Vitest results of the API unit tests (59)
A39: web-unit-tests.json | B39: Vitest results of the web unit tests at the evidence capture (81)
A40: api-e2e-tests.json | B40: Vitest results of the end-to-end suite (32)
A41: test-reruns.json | B41: Re-runs of the three suites by iorta QA on 2 October 2026 (59, 91 and 32 tests); the later result is the status shown
A42: security-checks.json | B42: 29 OWASP checks (see the Security Assessment Report)
A43: api-test-run.json | B43: API run of 113 cases: 111 passed, 2 not passed; started 2026-10-02 22:12 UTC
A44: ui-screens/ | B44: Screen captures cited by the manual cases (JPEG copies of the PNG captures)
A46: Conventions
A47: • Demonstration users: ag-000001 (agency principal), ag-000002 (sub-agent), ag-000003 (principal of another agency), bk-000004 and bk-000005 (bank officers; the bank is blocked for new business), manager, ops.maker, ops.checker, underwriter, finance, compliance, support, admin.
A48: • Dates in the execution log are UTC; the application's business day is the Brunei calendar day (UTC+8).
...

Sheet Summary
A4: SalesVerse 2.0 – Test status summary
A5: As of 2 October 2026 (commit af2fb05); formulas count the Cases sheet, 'Catalogue' is the generator's count
A7: Catalogue size
A8: Item | B8: Count | C8: Catalogue | D8: Check
A9: Test scenarios | B9: =COUNTA(Scenarios!A:A)-1 | C9: 70 | D9: =IF(B9=C9,"OK","DRIFT")
A10: Test conditions | B10: =COUNTA(Conditions!A:A)-1 | C10: 196 | D10: =IF(B10=C10,"OK","DRIFT")
A11: Test cases | B11: =COUNTA(Cases!A:A)-1 | C11: 438 | D11: =IF(B11=C11,"OK","DRIFT")
A13: Cases by status
A14: Status | B14: Cases | C14: Catalogue | D14: Check | E14: Share
A15: Status: Passed | B15: =COUNTIF(Cases!$L:$L,"Passed") | C15: 384 | D15: =IF(B15=C15,"OK","DRIFT") | E15: =B15/$B$19
A16: Status: Failed | B16: =COUNTIF(Cases!$L:$L,"Failed") | C16: 2 | D16: =IF(B16=C16,"OK","DRIFT") | E16: =B16/$B$19
A17: Status: Blocked | B17: =COUNTIF(Cases!$L:$L,"Blocked") | C17: 1 | D17: =IF(B17=C17,"OK","DRIFT") | E17: =B17/$B$19
A18: Status: Not executed | B18: =COUNTIF(Cases!$L:$L,"Not executed") | C18: 51 | D18: =IF(B18=C18,"OK","DRIFT") | E18: =B18/$B$19
A19: Total | B19: =SUM(B15:B18) | C19: =SUM(C15:C18) | D19: =IF(B19=C19,"OK","DRIFT") | E19: =B19/$B$19
A21: Cases by level
A22: Level | B22: Cases | C22: Passed | D22: Failed | E22: Blocked | F22: Not executed | G22: Catalogue | H22: Check
A23: Unit (API and web components) | B23: =COUNTIF(Cases!$J:$J,"Unit") | C23: =COUNTIFS(Cases!$J:$J,"Unit",Cases!$L:$L,"Passed") | D23: =COUNTIFS(Cases!$J:$J,"Unit",Cases!$L:$L,"Failed") | E23: =COUNTIFS(Cases!$J:$J,"Unit",Cases!$L:$L,"Blocked") | F23: =COUNTIFS(Cases!$J:$J,"Unit",Cases!$L:$L,"Not executed") | G23: 150 | H23: =IF(B23=G23,"OK","DRIFT")
A24: API system cases executed against the running system | B24: =COUNTIF(Cases!$J:$J,"API") | C24: =COUNTIFS(Cases!$J:$J,"API",Cases!$L:$L,"Passed") | D24: =COUNTIFS(Cases!$J:$J,"API",Cases!$L:$L,"Failed") | E24: =COUNTIFS(Cases!$J:$J,"API",Cases!$L:$L,"Blocked") | F24: =COUNTIFS(Cases!$J:$J,"API",Cases!$L:$L,"Not executed") | G24: 122 | H24: =IF(B24=G24,"OK","DRIFT")
A25: End-to-end API suite (business journeys) | B25: =COUNTIF(Cases!$J:$J,"E2E") | C25: =COUNTIFS(Cases!$J:$J,"E2E",Cases!$L:$L,"Passed") | D25: =COUNTIFS(Cases!$J:$J,"E2E",Cases!$L:$L,"Failed") | E25: =COUNTIFS(Cases!$J:$J,"E2E",Cases!$L:$L,"Blocked") | F25: =COUNTIFS(Cases!$J:$J,"E2E",Cases!$L:$L,"Not executed") | G25: 44 | H25: =IF(B25=G25,"OK","DRIFT")
A26: User interface (manual, exploratory) | B26: =COUNTIF(Cases!$J:$J,"UI") | C26: =COUNTIFS(Cases!$J:$J,"UI",Cases!$L:$L,"Passed") | D26: =COUNTIFS(Cases!$J:$J,"UI",Cases!$L:$L,"Failed") | E26: =COUNTIFS(Cases!$J:$J,"UI",Cases!$L:$L,"Blocked") | F26: =COUNTIFS(Cases!$J:$J,"UI",Cases!$L:$L,"Not executed") | G26: 57 | H26: =IF(B26=G26,"OK","DRIFT")
A27: Security checks (OWASP Top 10) | B27: =COUNTIF(Cases!$J:$J,"Security") | C27: =COUNTIFS(Cases!$J:$J,"Security",Cases!$L:$L,"Passed") | D27: =COUNTIFS(Cases!$J:$J,"Security",Cases!$L:$L,"Failed") | E27: =COUNTIFS(Cases!$J:$J,"Security",Cases!$L:$L,"Blocked") | F27: =COUNTIFS(Cases!$J:$J,"Security",Cases!$L:$L,"Not executed") | G27: 34 | H27: =IF(B27=G27,"OK","DRIFT")
A28: System integration test with IIFT systems | B28: =COUNTIF(Cases!$J:$J,"SIT") | C28: =COUNTIFS(Cases!$J:$J,"SIT",Cases!$L:$L,"Passed") | D28: =COUNTIFS(Cases!$J:$J,"SIT",Cases!$L:$L,"Failed") | E28: =COUNTIFS(Cases!$J:$J,"SIT",Cases!$L:$L,"Blocked") | F28: =COUNTIFS(Cases!$J:$J,"SIT",Cases!$L:$L,"Not executed") | G28: 25 | H28: =IF(B28=G28,"OK","DRIFT")
A29: Performance | B29: =COUNTIF(Cases!$J:$J,"Perf") | C29: =COUNTIFS(Cases!$J:$J,"Perf",Cases!$L:$L,"Passed") | D29: =COUNTIFS(Cases!$J:$J,"Perf",Cases!$L:$L,"Failed") | E29: =COUNTIFS(Cases!$J:$J,"Perf",Cases!$L:$L,"Blocked") | F29: =COUNTIFS(Cases!$J:$J,"Perf",Cases!$L:$L,"Not executed") | G29: 3 | H29: =IF(B29=G29,"OK","DRIFT")
A30: User acceptance | B30: =COUNTIF(Cases!$J:$J,"UAT") | C30: =COUNTIFS(Cases!$J:$J,"UAT",Cases!$L:$L,"Passed") | D30: =COUNTIFS(Cases!$J:$J,"UAT",Cases!$L:$L,"Failed") | E30: =COUNTIFS(Cases!$J:$J,"UAT",Cases!$L:$L,"Blocked") | F30: =COUNTIFS(Cases!$J:$J,"UAT",Cases!$L:$L,"Not executed") | G30: 3 | H30: =IF(B30=G30,"OK","DRIFT")
A31: Total | B31: =SUM(B23:B30) | C31: =SUM(C23:C30) | D31: =SUM(D23:D30) | E31: =SUM(E23:E30) | F31: =SUM(F23:F30) | G31: =SUM(G23:G30) | H31: =IF(B31=G31,"OK","DRIFT")
A33: Cases by RFP area
A34: Area | B34: Cases | C34: Passed | D34: Failed | E34: Blocked | F34: Not executed | G34: Catalogue | H34: Check
A35: AUT – Authentication and session | B35: =COUNTIF(Cases!$D:$D,"AUT") | C35: =COUNTIFS(Cases!$D:$D,"AUT",Cases!$L:$L,"Passed") | D35: =COUNTIFS(Cases!$D:$D,"AUT",Cases!$L:$L,"Failed") | E35: =COUNTIFS(Cases!$D:$D,"AUT",Cases!$L:$L,"Blocked") | F35: =COUNTIFS(Cases!$D:$D,"AUT",Cases!$L:$L,"Not executed") | G35: 37 | H35: =IF(B35=G35,"OK","DRIFT")
A36: ACC – Access control and data scoping | B36: =COUNTIF(Cases!$D:$D,"ACC") | C36: =COUNTIFS(Cases!$D:$D,"ACC",Cases!$L:$L,"Passed") | D36: =COUNTIFS(Cases!$D:$D,"ACC",Cases!$L:$L,"Failed") | E36: =COUNTIFS(Cases!$D:$D,"ACC",Cases!$L:$L,"Blocked") | F36: =COUNTIFS(Cases!$D:$D,"ACC",Cases!$L:$L,"Not executed") | G36: 15 | H36: =IF(B36=G36,"OK","DRIFT")
A37: AGT – Agent and agency management | B37: =COUNTIF(Cases!$D:$D,"AGT") | C37: =COUNTIFS(Cases!$D:$D,"AGT",Cases!$L:$L,"Passed") | D37: =COUNTIFS(Cases!$D:$D,"AGT",Cases!$L:$L,"Failed") | E37: =COUNTIFS(Cases!$D:$D,"AGT",Cases!$L:$L,"Blocked") | F37: =COUNTIFS(Cases!$D:$D,"AGT",Cases!$L:$L,"Not executed") | G37: 18 | H37: =IF(B37=G37,"OK","DRIFT")
A38: PAR – Participant management | B38: =COUNTIF(Cases!$D:$D,"PAR") | C38: =COUNTIFS(Cases!$D:$D,"PAR",Cases!$L:$L,"Passed") | D38: =COUNTIFS(Cases!$D:$D,"PAR",Cases!$L:$L,"Failed") | E38: =COUNTIFS(Cases!$D:$D,"PAR",Cases!$L:$L,"Blocked") | F38: =COUNTIFS(Cases!$D:$D,"PAR",Cases!$L:$L,"Not executed") | G38: 11 | H38: =IF(B38=G38,"OK","DRIFT")
A39: AML – AML/KYC screening | B39: =COUNTIF(Cases!$D:$D,"AML") | C39: =COUNTIFS(Cases!$D:$D,"AML",Cases!$L:$L,"Passed") | D39: =COUNTIFS(Cases!$D:$D,"AML",Cases!$L:$L,"Failed") | E39: =COUNTIFS(Cases!$D:$D,"AML",Cases!$L:$L,"Blocked") | F39: =COUNTIFS(Cases!$D:$D,"AML",Cases!$L:$L,"Not executed") | G39: 14 | H39: =IF(B39=G39,"OK","DRIFT")
A40: PRD – Products and rating | B40: =COUNTIF(Cases!$D:$D,"PRD") | C40: =COUNTIFS(Cases!$D:$D,"PRD",Cases!$L:$L,"Passed") | D40: =COUNTIFS(Cases!$D:$D,"PRD",Cases!$L:$L,"Failed") | E40: =COUNTIFS(Cases!$D:$D,"PRD",Cases!$L:$L,"Blocked") | F40: =COUNTIFS(Cases!$D:$D,"PRD",Cases!$L:$L,"Not executed") | G40: 36 | H40: =IF(B40=G40,"OK","DRIFT")
A41: QUO – Quotation and submission | B41: =COUNTIF(Cases!$D:$D,"QUO") | C41: =COUNTIFS(Cases!$D:$D,"QUO",Cases!$L:$L,"Passed") | D41: =COUNTIFS(Cases!$D:$D,"QUO",Cases!$L:$L,"Failed") | E41: =COUNTIFS(Cases!$D:$D,"QUO",Cases!$L:$L,"Blocked") | F41: =COUNTIFS(Cases!$D:$D,"QUO",Cases!$L:$L,"Not executed") | G41: 31 | H41: =IF(B41=G41,"OK","DRIFT")
A42: WFL – Approval workflow (maker-checker) | B42: =COUNTIF(Cases!$D:$D,"WFL") | C42: =COUNTIFS(Cases!$D:$D,"WFL",Cases!$L:$L,"Passed") | D42: =COUNTIFS(Cases!$D:$D,"WFL",Cases!$L:$L,"Failed") | E42: =COUNTIFS(Cases!$D:$D,"WFL",Cases!$L:$L,"Blocked") | F42: =COUNTIFS(Cases!$D:$D,"WFL",Cases!$L:$L,"Not executed") | G42: 10 | H42: =IF(B42=G42,"OK","DRIFT")
A43: POL – Policy issuance and policy documents | B43: =COUNTIF(Cases!$D:$D,"POL") | C43: =COUNTIFS(Cases!$D:$D,"POL",Cases!$L:$L,"Passed") | D43: =COUNTIFS(Cases!$D:$D,"POL",Cases!$L:$L,"Failed") | E43: =COUNTIFS(Cases!$D:$D,"POL",Cases!$L:$L,"Blocked") | F43: =COUNTIFS(Cases!$D:$D,"POL",Cases!$L:$L,"Not executed") | G43: 12 | H43: =IF(B43=G43,"OK","DRIFT")
A44: BIL – Billing and payments | B44: =COUNTIF(Cases!$D:$D,"BIL") | C44: =COUNTIFS(Cases!$D:$D,"BIL",Cases!$L:$L,"Passed") | D44: =COUNTIFS(Cases!$D:$D,"BIL",Cases!$L:$L,"Failed") | E44: =COUNTIFS(Cases!$D:$D,"BIL",Cases!$L:$L,"Blocked") | F44: =COUNTIFS(Cases!$D:$D,"BIL",Cases!$L:$L,"Not executed") | G44: 17 | H44: =IF(B44=G44,"OK","DRIFT")
A45: SVC – Policy servicing: renewal, endorsement, cancellation | B45: =COUNTIF(Cases!$D:$D,"SVC") | C45: =COUNTIFS(Cases!$D:$D,"SVC",Cases!$L:$L,"Passed") | D45: =COUNTIFS(Cases!$D:$D,"SVC",Cases!$L:$L,"Failed") | E45: =COUNTIFS(Cases!$D:$D,"SVC",Cases!$L:$L,"Blocked") | F45: =COUNTIFS(Cases!$D:$D,"SVC",Cases!$L:$L,"Not executed") | G45: 10 | H45: =IF(B45=G45,"OK","DRIFT")
A46: CLM – Claims notification | B46: =COUNTIF(Cases!$D:$D,"CLM") | C46: =COUNTIFS(Cases!$D:$D,"CLM",Cases!$L:$L,"Passed") | D46: =COUNTIFS(Cases!$D:$D,"CLM",Cases!$L:$L,"Failed") | E46: =COUNTIFS(Cases!$D:$D,"CLM",Cases!$L:$L,"Blocked") | F46: =COUNTIFS(Cases!$D:$D,"CLM",Cases!$L:$L,"Not executed") | G46: 5 | H46: =IF(B46=G46,"OK","DRIFT")
A47: DOC – Documents and uploads | B47: =COUNTIF(Cases!$D:$D,"DOC") | C47: =COUNTIFS(Cases!$D:$D,"DOC",Cases!$L:$L,"Passed") | D47: =COUNTIFS(Cases!$D:$D,"DOC",Cases!$L:$L,"Failed") | E47: =COUNTIFS(Cases!$D:$D,"DOC",Cases!$L:$L,"Blocked") | F47: =COUNTIFS(Cases!$D:$D,"DOC",Cases!$L:$L,"Not executed") | G47: 14 | H47: =IF(B47=G47,"OK","DRIFT")
...

Sheet Scenarios
A1: ID | B1: Area | C1: RFP IDs | D1: Persona | E1: Scenario | F1: Pre-conditions | G1: Expected end state | H1: Conditions | I1: Cases
A2: TS-01 | B2: AUT – Authentication and session | C2: AP-01, BO-01, NFR-09 | D2: Agent, bank officer, staff | E2: Sign in with a user name and password; wrong credentials are refused without revealing which part was wrong. | F2: Demonstration users loaded; account active. | G2: Session established; failed attempts recorded in the audit trail. | H2: =COUNTIF(Conditions!$B:$B,A2) | I2: =COUNTIF(Cases!$B:$B,A2)
A3: TS-02 | B3: AUT – Authentication and session | C3: AP-02, NFR-09 | D3: Any user, administrator | E3: Change a password under the configurable policy (length, character classes, history, expiry, no user name); temporary passwords must be changed at first sign-in. | F3: Signed in; password parameters at defaults. | G3: Password changed; other sessions ended; policy breaches refused. | H3: =COUNTIF(Conditions!$B:$B,A3) | I3: =COUNTIF(Cases!$B:$B,A3)
A4: TS-03 | B4: AUT – Authentication and session | C4: AP-03, NFR-09 | D4: Any user | E4: Session management: cookie flags, new session id at sign-in, logout revocation, single active session, idle and absolute timeout. | F4: Signed in. | G4: Old sessions unusable; timeouts applied from parameters. | H4: =COUNTIF(Conditions!$B:$B,A4) | I4: =COUNTIF(Cases!$B:$B,A4)
A5: TS-04 | B5: AUT – Authentication and session | C5: AP-04, NFR-09 | D5: Any user, administrator | E5: Account lockout after the configured failed attempts and administrator unlock. | F5: Lockout parameters at defaults (5 attempts, 30 minutes). | G5: Account locked then unlocked; events audited. | H5: =COUNTIF(Conditions!$B:$B,A5) | I5: =COUNTIF(Cases!$B:$B,A5)
A6: TS-05 | B6: AUT – Authentication and session | C6: INT-06, BO-01 | D6: Back-office staff | E6: Back-office sign-on through the corporate directory (LDAP/Active Directory) with escaped filters. | F6: LDAP configured (IIFT environment). | G6: Directory users sign in; local accounts unaffected. | H6: =COUNTIF(Conditions!$B:$B,A6) | I6: =COUNTIF(Cases!$B:$B,A6)
A7: TS-06 | B7: ACC – Access control and data scoping | C7: AP-59, BO-02, COM-02, NFR-10 | D7: All personas | E7: Role-based access: every route checks a permission; portal and back-office audiences are separate; roles grant least privilege. | F7: Demonstration roles loaded. | G7: Unauthorised calls refused with 401/403; authorised calls succeed. | H7: =COUNTIF(Conditions!$B:$B,A7) | I7: =COUNTIF(Cases!$B:$B,A7)
A8: TS-07 | B8: ACC – Access control and data scoping | C8: AP-09, AP-11, AP-12, AP-59, COM-02 | D8: Agents, bank officers, supervisors | E8: Data scoping: agents see their own and their sub-agents' records; principals and bank supervisors see the whole agency/bank; other agencies' records are not disclosed. | F8: Two agencies and one bank with business. | G8: Records outside the scope answer 404/403; participant profile shared only through exact-ID lookup. | H8: =COUNTIF(Conditions!$B:$B,A8) | I8: =COUNTIF(Cases!$B:$B,A8)
A9: TS-08 | B9: AGT – Agent and agency management | C9: AP-07, AP-08, AP-48, BO-10, BO-11 | D9: Agency principal, operations checker | E9: Online registration of a sub-agent with AML screening, document upload and maker-checker approval; agent code generated; portal account created. | F9: Principal signed in; checker available. | G9: Agent ACTIVE with a unique code and a user that must change its temporary password. | H9: =COUNTIF(Conditions!$B:$B,A9) | I9: =COUNTIF(Cases!$B:$B,A9)
A10: TS-09 | B10: AGT – Agent and agency management | C10: AP-05, AP-06, AP-09, AP-10, BO-08 | D10: Agent, bank officer | E10: Profile, agency information and hierarchy views; profile changes submitted for approval and withdrawable by the maker. | F10: Signed in as a sub-agent. | G10: Profile request pending or withdrawn; hierarchy shows the reporting line. | H10: =COUNTIF(Conditions!$B:$B,A10) | I10: =COUNTIF(Cases!$B:$B,A10)
A11: TS-10 | B11: AGT – Agent and agency management | C11: BO-05, BO-06, BO-07, BO-08, BO-09 | D11: Operations maker/checker, manager | E11: Back-office agent and agency administration: search, status changes with allowed transitions, agency creation and maintenance, payment-block lift. | F11: Back-office user with the relevant permissions. | G11: Changes applied after approval; invalid transitions refused. | H11: =COUNTIF(Conditions!$B:$B,A11) | I11: =COUNTIF(Cases!$B:$B,A11)
A12: TS-11 | B12: PAR – Participant management | C12: AP-13, AP-14, AP-15, AP-48, NFR-30 | D12: Agent, operations checker | E12: Register individual and corporate participants with validation, search them, and submit profile updates for approval. | F12: Signed in as an agent. | G12: Participant number assigned; updates applied after approval. | H12: =COUNTIF(Conditions!$B:$B,A12) | I12: =COUNTIF(Cases!$B:$B,A12)
A13: TS-12 | B13: PAR – Participant management | C13: AP-11, AP-12, COM-01 | D13: Agents of different agencies | E13: Single shared participant profile: duplicate identification numbers refused, exact-ID lookup across agencies returns a masked summary, full profile visible once business exists. | F13: Participant registered by agency A. | G13: No duplicate profiles; cross-agency visibility limited as designed. | H13: =COUNTIF(Conditions!$B:$B,A13) | I13: =COUNTIF(Cases!$B:$B,A13)
... A71: TS-70 | B71: PLT – Platform behaviour and configuration | C71: NFR-22 | D71: Developer, QA | E71: Web application components: API client (CSRF, session end), formatting, status display, navigation, permission gating, forms. | F71: Unit test environment. | G71: Components behave per specification. | H71: =COUNTIF(Conditions!$B:$B,A71) | I71: =COUNTIF(Cases!$B:$B,A71)

Sheet Conditions
A1: ID | B1: Scenario | C1: Area | D1: Condition / rule under test | E1: Cases | F1: Passed | G1: Failed | H1: Blocked | I1: Not executed
A2: TC-001 | B2: TS-01 | C2: AUT – Authentication and session | D2: Unknown user and wrong password return the same message and code INVALID_CREDENTIALS | E2: =COUNTIF(Cases!$C:$C,A2) | F2: =COUNTIFS(Cases!$C:$C,A2,Cases!$L:$L,"Passed") | G2: =COUNTIFS(Cases!$C:$C,A2,Cases!$L:$L,"Failed") | H2: =COUNTIFS(Cases!$C:$C,A2,Cases!$L:$L,"Blocked") | I2: =COUNTIFS(Cases!$C:$C,A2,Cases!$L:$L,"Not executed")
A3: TC-002 | B3: TS-01 | C3: AUT – Authentication and session | D3: Successful sign-in returns the user profile, permissions and a CSRF token; never a password hash | E3: =COUNTIF(Cases!$C:$C,A3) | F3: =COUNTIFS(Cases!$C:$C,A3,Cases!$L:$L,"Passed") | G3: =COUNTIFS(Cases!$C:$C,A3,Cases!$L:$L,"Failed") | H3: =COUNTIFS(Cases!$C:$C,A3,Cases!$L:$L,"Blocked") | I3: =COUNTIFS(Cases!$C:$C,A3,Cases!$L:$L,"Not executed")
A4: TC-003 | B4: TS-01 | C4: AUT – Authentication and session | D4: Failed sign-ins are recorded in the audit trail with the client IP address | E4: =COUNTIF(Cases!$C:$C,A4) | F4: =COUNTIFS(Cases!$C:$C,A4,Cases!$L:$L,"Passed") | G4: =COUNTIFS(Cases!$C:$C,A4,Cases!$L:$L,"Failed") | H4: =COUNTIFS(Cases!$C:$C,A4,Cases!$L:$L,"Blocked") | I4: =COUNTIFS(Cases!$C:$C,A4,Cases!$L:$L,"Not executed")
A5: TC-004 | B5: TS-01 | C5: AUT – Authentication and session | D5: Sign-in attempts are rate limited per client address (HTTP 429) | E5: =COUNTIF(Cases!$C:$C,A5) | F5: =COUNTIFS(Cases!$C:$C,A5,Cases!$L:$L,"Passed") | G5: =COUNTIFS(Cases!$C:$C,A5,Cases!$L:$L,"Failed") | H5: =COUNTIFS(Cases!$C:$C,A5,Cases!$L:$L,"Blocked") | I5: =COUNTIFS(Cases!$C:$C,A5,Cases!$L:$L,"Not executed")
A6: TC-005 | B6: TS-01 | C6: AUT – Authentication and session | D6: Injection payloads in sign-in fields are rejected as invalid credentials | E6: =COUNTIF(Cases!$C:$C,A6) | F6: =COUNTIFS(Cases!$C:$C,A6,Cases!$L:$L,"Passed") | G6: =COUNTIFS(Cases!$C:$C,A6,Cases!$L:$L,"Failed") | H6: =COUNTIFS(Cases!$C:$C,A6,Cases!$L:$L,"Blocked") | I6: =COUNTIFS(Cases!$C:$C,A6,Cases!$L:$L,"Not executed")
A7: TC-006 | B7: TS-01 | C7: AUT – Authentication and session | D7: Sign-in page validates both fields and shows the server's error message | E7: =COUNTIF(Cases!$C:$C,A7) | F7: =COUNTIFS(Cases!$C:$C,A7,Cases!$L:$L,"Passed") | G7: =COUNTIFS(Cases!$C:$C,A7,Cases!$L:$L,"Failed") | H7: =COUNTIFS(Cases!$C:$C,A7,Cases!$L:$L,"Blocked") | I7: =COUNTIFS(Cases!$C:$C,A7,Cases!$L:$L,"Not executed")
A8: TC-007 | B8: TS-02 | C8: AUT – Authentication and session | D8: Password must meet the configured length and character-class rules and must not contain the user name | E8: =COUNTIF(Cases!$C:$C,A8) | F8: =COUNTIFS(Cases!$C:$C,A8,Cases!$L:$L,"Passed") | G8: =COUNTIFS(Cases!$C:$C,A8,Cases!$L:$L,"Failed") | H8: =COUNTIFS(Cases!$C:$C,A8,Cases!$L:$L,"Blocked") | I8: =COUNTIFS(Cases!$C:$C,A8,Cases!$L:$L,"Not executed")
A9: TC-008 | B9: TS-02 | C9: AUT – Authentication and session | D9: Last N passwords cannot be reused and passwords expire after the configured days | E9: =COUNTIF(Cases!$C:$C,A9) | F9: =COUNTIFS(Cases!$C:$C,A9,Cases!$L:$L,"Passed") | G9: =COUNTIFS(Cases!$C:$C,A9,Cases!$L:$L,"Failed") | H9: =COUNTIFS(Cases!$C:$C,A9,Cases!$L:$L,"Blocked") | I9: =COUNTIFS(Cases!$C:$C,A9,Cases!$L:$L,"Not executed")
A10: TC-009 | B10: TS-02 | C10: AUT – Authentication and session | D10: Passwords are hashed with Argon2id; current password must be given to change it | E10: =COUNTIF(Cases!$C:$C,A10) | F10: =COUNTIFS(Cases!$C:$C,A10,Cases!$L:$L,"Passed") | G10: =COUNTIFS(Cases!$C:$C,A10,Cases!$L:$L,"Failed") | H10: =COUNTIFS(Cases!$C:$C,A10,Cases!$L:$L,"Blocked") | I10: =COUNTIFS(Cases!$C:$C,A10,Cases!$L:$L,"Not executed")
A11: TC-010 | B11: TS-02 | C11: AUT – Authentication and session | D11: A temporary password must be changed before any other request succeeds (PASSWORD_CHANGE_REQUIRED) | E11: =COUNTIF(Cases!$C:$C,A11) | F11: =COUNTIFS(Cases!$C:$C,A11,Cases!$L:$L,"Passed") | G11: =COUNTIFS(Cases!$C:$C,A11,Cases!$L:$L,"Failed") | H11: =COUNTIFS(Cases!$C:$C,A11,Cases!$L:$L,"Blocked") | I11: =COUNTIFS(Cases!$C:$C,A11,Cases!$L:$L,"Not executed")
A12: TC-011 | B12: TS-02 | C12: AUT – Authentication and session | D12: Generated temporary passwords satisfy the policy | E12: =COUNTIF(Cases!$C:$C,A12) | F12: =COUNTIFS(Cases!$C:$C,A12,Cases!$L:$L,"Passed") | G12: =COUNTIFS(Cases!$C:$C,A12,Cases!$L:$L,"Failed") | H12: =COUNTIFS(Cases!$C:$C,A12,Cases!$L:$L,"Blocked") | I12: =COUNTIFS(Cases!$C:$C,A12,Cases!$L:$L,"Not executed")
A13: TC-012 | B13: TS-03 | C13: AUT – Authentication and session | D13: Session cookie is HttpOnly and SameSite=Strict; Secure in production | E13: =COUNTIF(Cases!$C:$C,A13) | F13: =COUNTIFS(Cases!$C:$C,A13,Cases!$L:$L,"Passed") | G13: =COUNTIFS(Cases!$C:$C,A13,Cases!$L:$L,"Failed") | H13: =COUNTIFS(Cases!$C:$C,A13,Cases!$L:$L,"Blocked") | I13: =COUNTIFS(Cases!$C:$C,A13,Cases!$L:$L,"Not executed")
... A197: TC-196 | B197: TS-70 | C197: PLT – Platform behaviour and configuration | D197: Sign-in page behaviour | E197: =COUNTIF(Cases!$C:$C,A197) | F197: =COUNTIFS(Cases!$C:$C,A197,Cases!$L:$L,"Passed") | G197: =COUNTIFS(Cases!$C:$C,A197,Cases!$L:$L,"Failed") | H197: =COUNTIFS(Cases!$C:$C,A197,Cases!$L:$L,"Blocked") | I197: =COUNTIFS(Cases!$C:$C,A197,Cases!$L:$L,"Not executed")

Sheet Cases
A1: ID | B1: Scenario | C1: Condition | D1: Area | E1: Title | F1: Persona / user | G1: Steps | H1: Test data | I1: Expected result | J1: Level | K1: Automation | L1: Status | M1: Evidence | N1: Executed on | O1: Executed by | P1: Defect ref
A2: CS-0001 | B2: TS-01 | C2: TC-001 | D2: AUT | E2: Wrong password and unknown user get the same generic 401 | F2: anonymous | G2: 1. POST /api/v1/auth/login with an unknown user name 2. POST /api/v1/auth/login as finance with a wrong password 3. Compare status, code and message | H2: username nobody-<run>; finance / wrong-password | I2: HTTP 401 INVALID_CREDENTIALS for both; identical message | J2: API | K2: Executed – API run (tools/testing/api-test-run.mjs) | L2: Passed | M2: api-test-run.json EX-001: POST /api/v1/auth/login (unknown user; finance with wrong password) → 401 INVALID_CREDENTIALS – Invalid username or password | 401 INVALID_CREDENTIALS – Invalid username or password | N2: 2 Oct 2026 22:12 UTC | O2: iorta TechNXT QA (API run)
A3: CS-0002 | B3: TS-01 | C3: TC-001 | D3: AUT | E3: Generic message for wrong credentials (suite) | F3: finance, support, ag-000001..3, admin | G3: 1. Run `npm run test:e2e -w apps/api` (rebuilds the iift_test database from the migrations and seeds) 2. Sign in as 'nobody' and as finance with a wrong password | H3: Unknown user; wrong password | I3: Both 401 INVALID_CREDENTIALS with identical message | J3: E2E | K3: Automated – apps/api/test/auth.e2e-spec.ts › rejects wrong credentials with a generic message | L3: Passed | M3: api-e2e-tests.json: 'Authentication and session security (AP-01..04, BO-01) rejects wrong credentials with a generic message' passed (2 Oct 2026 14:55 UTC); test-reruns.json: passed (2 Oct 2026 22:00 UTC) | N3: 2 Oct 2026 22:00 UTC | O3: iorta QA (Vitest e2e, iift_test database)
A4: CS-0003 | B4: TS-01 | C4: TC-001 | D4: AUT | E4: SEC-04 (OWASP A07): Same response for unknown user and wrong password (no user enumeration) | F4: Security tester | G4: 1. Run `node tools/security/security-checks.mjs` against a fresh non-production instance with demonstration data 2. Read the result of SEC-04 | H4: Demonstration users and records; crafted payloads as described in the script | I4: Identical message for unknown user and wrong password | J4: Security | K4: Automated – tools/security/security-checks.mjs | L4: Passed | M4: security-checks.json: SEC-04 PASS (2 Oct 2026 14:57 UTC); evidence summarised in the Security Assessment Report | N4: 2 Oct 2026 14:57 UTC | O4: iorta QA (security-checks.mjs)
A5: CS-0004 | B5: TS-01 | C5: TC-002 | D5: AUT | E5: Successful sign-in issues a HttpOnly SameSite=Strict cookie and a CSRF token | F5: ag-000001 | G5: 1. POST /api/v1/auth/login as ag-000001 2. Inspect Set-Cookie flags and the body | H5: ag-000001 / demo password | I5: HTTP 200; Set-Cookie has HttpOnly and SameSite=Strict; csrfToken present; no password hash in body | J5: API | K5: Executed – API run (tools/testing/api-test-run.mjs) | L5: Passed | M5: api-test-run.json EX-002: POST /api/v1/auth/login → 200; Set-Cookie flags: Path=/, HttpOnly, SameSite=Strict; csrfToken present | N5: 2 Oct 2026 22:12 UTC | O5: iorta TechNXT QA (API run)
A6: CS-0005 | B6: TS-01 | C6: TC-003 | D6: AUT | E6: SEC-27 (OWASP A09): Failed sign-ins are recorded in the audit trail with IP address | F6: Security tester | G6: 1. Run `node tools/security/security-checks.mjs` against a fresh non-production instance with demonstration data 2. Read the result of SEC-27 | H6: Demonstration users and records; crafted payloads as described in the script | I6: LOGIN_FAILED events with IP address in the audit trail | J6: Security | K6: Automated – tools/security/security-checks.mjs | L6: Passed | M6: security-checks.json: SEC-27 PASS (2 Oct 2026 14:57 UTC); evidence summarised in the Security Assessment Report | N6: 2 Oct 2026 14:57 UTC | O6: iorta QA (security-checks.mjs)
A7: CS-0006 | B7: TS-01 | C7: TC-004 | D7: AUT | E7: SEC-08 (OWASP A07): Sign-in attempts are rate limited per client (HTTP 429) | F7: Security tester | G7: 1. Run `node tools/security/security-checks.mjs` against a fresh non-production instance with demonstration data 2. Read the result of SEC-08 | H7: Demonstration users and records; crafted payloads as described in the script | I7: HTTP 429 once the per-client sign-in limit is reached | J7: Security | K7: Automated – tools/security/security-checks.mjs | L7: Passed | M7: security-checks.json: SEC-08 PASS (2 Oct 2026 14:57 UTC); evidence summarised in the Security Assessment Report | N7: 2 Oct 2026 14:57 UTC | O7: iorta QA (security-checks.mjs)
A8: CS-0007 | B8: TS-01 | C8: TC-004 | D8: AUT | E8: Sign-in rate limit per client address | F8: Anonymous | G8: 1. Send 11 sign-in attempts within a minute from one address | H8: LOGIN_RATE_LIMIT_PER_MINUTE = 10 | I8: Attempts after the tenth answer 429 | J8: Security | K8: Not automated | L8: Not executed | M8: Not executed in this run (would block the run's own sign-ins); covered by automated check SEC-08
A9: CS-0008 | B9: TS-01 | C9: TC-005 | D9: AUT | E9: SEC-18 (OWASP A03): Injection in sign-in fields is rejected as invalid credentials | F9: Security tester | G9: 1. Run `node tools/security/security-checks.mjs` against a fresh non-production instance with demonstration data 2. Read the result of SEC-18 | H9: Demonstration users and records; crafted payloads as described in the script | I9: 401 invalid credentials | J9: Security | K9: Automated – tools/security/security-checks.mjs | L9: Passed | M9: security-checks.json: SEC-18 PASS (2 Oct 2026 14:57 UTC); evidence summarised in the Security Assessment Report | N9: 2 Oct 2026 14:57 UTC | O9: iorta QA (security-checks.mjs)
A10: CS-0009 | B10: TS-01 | C10: TC-006 | D10: AUT | E10: Sign-in page at desktop and mobile widths | F10: ag-000001 | G10: 1. Open /login at 1440, 1280 and 390 px 2. Sign in | H10: Demo password | I10: Form usable at every width; dashboard opens | J10: UI | K10: Manual (exploratory) | L10: Passed | M10: Screens: ui-login-1440.png, ui-login-390.png, a-login.png (evidence/ui-screens) | N10: 2 Oct 2026 | O10: iorta QA (manual, exploratory)
A11: CS-0010 | B11: TS-02 | C11: TC-007 | D11: AUT | E11: PasswordService: accepts a password meeting every rule | F11: Developer / CI | G11: 1. Run `npm test -w apps/api` (Vitest) 2. Locate 'PasswordService accepts a password meeting every rule' in the run output | H11: Fixtures defined in modules/auth/password.service.spec.ts | I11: The test passes: PasswordService accepts a password meeting every rule. | J11: Unit | K11: Automated – modules/auth/password.service.spec.ts | L11: Passed | M11: api-unit-tests.json: 'PasswordService accepts a password meeting every rule' passed (2 Oct 2026 14:55 UTC); test-reruns.json: passed (2 Oct 2026 21:45 UTC) | N11: 2 Oct 2026 21:45 UTC | O11: iorta QA (Vitest)
A12: CS-0011 | B12: TS-02 | C12: TC-007 | D12: AUT | E12: PasswordService: rejects passwords containing the username | F12: Developer / CI | G12: 1. Run `npm test -w apps/api` (Vitest) 2. Locate 'PasswordService rejects passwords containing the username' in the run output | H12: Fixtures defined in modules/auth/password.service.spec.ts | I12: The test passes: PasswordService rejects passwords containing the username. | J12: Unit | K12: Automated – modules/auth/password.service.spec.ts | L12: Passed | M12: api-unit-tests.json: 'PasswordService rejects passwords containing the username' passed (2 Oct 2026 14:55 UTC); test-reruns.json: passed (2 Oct 2026 21:45 UTC) | N12: 2 Oct 2026 21:45 UTC | O12: iorta QA (Vitest)
A13: CS-0012 | B13: TS-02 | C13: TC-007 | D13: AUT | E13: PasswordService: reports every unmet rule together | F13: Developer / CI | G13: 1. Run `npm test -w apps/api` (Vitest) 2. Locate 'PasswordService reports every unmet rule together' in the run output | H13: Fixtures defined in modules/auth/password.service.spec.ts | I13: The test passes: PasswordService reports every unmet rule together. | J13: Unit | K13: Automated – modules/auth/password.service.spec.ts | L13: Passed | M13: api-unit-tests.json: 'PasswordService reports every unmet rule together' passed (2 Oct 2026 14:55 UTC); test-reruns.json: passed (2 Oct 2026 21:45 UTC) | N13: 2 Oct 2026 21:45 UTC | O13: iorta QA (Vitest)
A14: CS-0013 | B14: TS-02 | C14: TC-007 | D14: AUT | E14: Password policy is enforced on change-password | F14: ag-000002 | G14: 1. POST /api/v1/auth/change-password with newPassword 'password1' 2. POST with a wrong currentPassword 3. GET /api/v1/auth/me | H14: ag-000002 | I14: HTTP 422 PASSWORD_POLICY for a weak password; 422 CURRENT_PASSWORD_INCORRECT when the current password is wrong; the demo password is unchanged | J14: API | K14: Executed – API run (tools/testing/api-test-run.mjs) | L14: Passed | M14: api-test-run.json EX-006: POST /api/v1/auth/change-password (weak new password; wrong current password) → 422 PASSWORD_POLICY – Password does not meet the password policy [At least 12 characters; An upper-case letter; A symbol] | 422 CURRENT_PASSWORD_INCORRECT – Current password is incorrect | session still valid: 200 | N14: 2 Oct 2026 22:12 UTC | O14: iorta TechNXT QA (API run)
A15: CS-0014 | B15: TS-02 | C15: TC-008 | D15: AUT | E15: PasswordService: expires passwords after the configured number of days | F15: Developer / CI | G15: 1. Run `npm test -w apps/api` (Vitest) 2. Locate 'PasswordService expires passwords after the configured number of days' in the run output | H15: Fixtures defined in modules/auth/password.service.spec.ts | I15: The test passes: PasswordService expires passwords after the configured number of days. | J15: Unit | K15: Automated – modules/auth/password.service.spec.ts | L15: Passed | M15: api-unit-tests.json: 'PasswordService expires passwords after the configured number of days' passed (2 Oct 2026 14:55 UTC); test-reruns.json: passed (2 Oct 2026 21:45 UTC) | N15: 2 Oct 2026 21:45 UTC | O15: iorta QA (Vitest)
A16: CS-0015 | B16: TS-02 | C16: TC-008 | D16: AUT | E16: Password history and expiry | F16: Agent | G16: 1. Change password 6 times cycling back to the first 2. Set expiry to 1 day; sign in after | H16: history_count 5, expiry_days | I16: Reuse of the last 5 refused; expired password forces a change | J16: SIT | K16: Not automated | L16: Not executed | M16: Not executed – changes demonstration account passwords; run in SIT with dedicated accounts
A17: CS-0016 | B17: TS-02 | C17: TC-009 | D17: AUT | E17: PasswordService: hashes with Argon2id and verifies | F17: Developer / CI | G17: 1. Run `npm test -w apps/api` (Vitest) 2. Locate 'PasswordService hashes with Argon2id and verifies' in the run output | H17: Fixtures defined in modules/auth/password.service.spec.ts | I17: The test passes: PasswordService hashes with Argon2id and verifies. | J17: Unit | K17: Automated – modules/auth/password.service.spec.ts | L17: Passed | M17: api-unit-tests.json: 'PasswordService hashes with Argon2id and verifies' passed (2 Oct 2026 14:55 UTC); test-reruns.json: passed (2 Oct 2026 21:45 UTC) | N17: 2 Oct 2026 21:45 UTC | O17: iorta QA (Vitest)
A18: CS-0017 | B18: TS-02 | C18: TC-010 | D18: AUT | E18: Temporary password must be changed first; weak passwords refused (suite) | F18: finance, support, ag-000001..3, admin | G18: 1. Run `npm run test:e2e -w apps/api` (rebuilds the iift_test database from the migrations and seeds) 2. Sign in as admin with the seeded temporary password 3. GET /backoffice/users 4. Change to 'password1' 5. Change to a strong password 6. GET /backoffice/users | H18: admin / Temp#Admin2026x | I18: 403 PASSWORD_CHANGE_REQUIRED; 422 PASSWORD_POLICY; 200; 200 | J18: E2E | K18: Automated – apps/api/test/auth.e2e-spec.ts › forces a temporary password to be changed before anything else | L18: Passed | M18: api-e2e-tests.json: 'Authentication and session security (AP-01..04, BO-01) forces a temporary password to be changed before anything else' passed (2 Oct 2026 14:55 UTC); test-reruns.json: passed (2 Oct 2026 22:00 UTC) | N18: 2 Oct 2026 22:00 UTC | O18: iorta QA (Vitest e2e, iift_test database)
A19: CS-0018 | B19: TS-02 | C19: TC-010 | D19: AUT | E19: Change-password page after first sign-in | F19: New user | G19: 1. Sign in with a temporary password 2. Observe the change-password page | H19: Temporary password | I19: Change-password page shown before any other page | J19: UI | K19: Manual (exploratory) | L19: Passed | M19: Screens: ui-change-password.png (evidence/ui-screens) | N19: 2 Oct 2026 | O19: iorta QA (manual, exploratory)
A20: CS-0019 | B20: TS-02 | C20: TC-011 | D20: AUT | E20: PasswordService: generates temporary passwords that satisfy the policy | F20: Developer / CI | G20: 1. Run `npm test -w apps/api` (Vitest) 2. Locate 'PasswordService generates temporary passwords that satisfy the policy' in the run output | H20: Fixtures defined in modules/auth/password.service.spec.ts | I20: The test passes: PasswordService generates temporary passwords that satisfy the policy. | J20: Unit | K20: Automated – modules/auth/password.service.spec.ts | L20: Passed | M20: api-unit-tests.json: 'PasswordService generates temporary passwords that satisfy the policy' passed (2 Oct 2026 14:55 UTC); test-reruns.json: passed (2 Oct 2026 21:45 UTC) | N20: 2 Oct 2026 21:45 UTC | O20: iorta QA (Vitest)
A21: CS-0020 | B21: TS-03 | C21: TC-012 | D21: AUT | E21: Session cookie flags and no secrets in the sign-in response (suite) | F21: finance, support, ag-000001..3, admin | G21: 1. Run `npm run test:e2e -w apps/api` (rebuilds the iift_test database from the migrations and seeds) 2. Sign in as finance 3. Inspect Set-Cookie and body | H21: finance | I21: HttpOnly, SameSite=Strict; no passwordHash or argon2 text | J21: E2E | K21: Automated – apps/api/test/auth.e2e-spec.ts › issues an HttpOnly, SameSite=Strict session cookie and never returns secrets | L21: Passed | M21: api-e2e-tests.json: 'Authentication and session security (AP-01..04, BO-01) issues an HttpOnly, SameSite=Strict session cookie and never returns secrets' passed (2 Oct 2026 14:55 UTC); test-reruns.json: passed (2 Oct 2026 22:00 UTC) | N21: 2 Oct 2026 22:00 UTC | O21: iorta QA (Vitest e2e, iift_test database)
A22: CS-0021 | B22: TS-03 | C22: TC-012 | D22: AUT | E22: SEC-05 (OWASP A07): Session cookie is HttpOnly and SameSite=Strict (Secure is enforced in production configuration) | F22: Security tester | G22: 1. Run `node tools/security/security-checks.mjs` against a fresh non-production instance with demonstration data 2. Read the result of SEC-05 | H22: Demonstration users and records; crafted payloads as described in the script | I22: HttpOnly and SameSite=Strict; Secure enforced by production configuration | J22: Security | K22: Automated – tools/security/security-checks.mjs | L22: Passed | M22: security-checks.json: SEC-05 PASS (2 Oct 2026 14:57 UTC); evidence summarised in the Security Assessment Report | N22: 2 Oct 2026 14:57 UTC | O22: iorta QA (security-checks.mjs)
A23: CS-0022 | B23: TS-03 | C23: TC-013 | D23: AUT | E23: SEC-06 (OWASP A07): Session identifier changes at every sign-in (no session fixation) | F23: Security tester | G23: 1. Run `node tools/security/security-checks.mjs` against a fresh non-production instance with demonstration data 2. Read the result of SEC-06 | H23: Demonstration users and records; crafted payloads as described in the script | I23: New session identifier after sign-in | J23: Security | K23: Automated – tools/security/security-checks.mjs | L23: Passed | M23: security-checks.json: SEC-06 PASS (2 Oct 2026 14:57 UTC); evidence summarised in the Security Assessment Report | N23: 2 Oct 2026 14:57 UTC | O23: iorta QA (security-checks.mjs)
A24: CS-0023 | B24: TS-03 | C24: TC-014 | D24: AUT | E24: Logout ends the session server-side | F24: ag-000003 | G24: 1. Sign in as ag-000003 2. GET /api/v1/auth/me 3. POST /api/v1/auth/logout 4. GET /api/v1/auth/me with the same cookie | H24: ag-000003 | I24: GET /auth/me 200 before logout, 401 NOT_AUTHENTICATED after | J24: API | K24: Executed – API run (tools/testing/api-test-run.mjs) | L24: Passed | M24: api-test-run.json EX-007: GET /api/v1/auth/me; POST /api/v1/auth/logout; GET /api/v1/auth/me → 200 | 204 | 401 NOT_AUTHENTICATED – Please sign in | N24: 2 Oct 2026 22:12 UTC | O24: iorta TechNXT QA (API run)
A25: CS-0024 | B25: TS-03 | C25: TC-014 | D25: AUT | E25: Logout ends the session (suite) | F25: finance, support, ag-000001..3, admin | G25: 1. Run `npm run test:e2e -w apps/api` (rebuilds the iift_test database from the migrations and seeds) 2. GET /auth/me, logout, GET /auth/me | H25: ag-000002 | I25: 200; 204; 401 | J25: E2E | K25: Automated – apps/api/test/auth.e2e-spec.ts › ends the session on logout | L25: Passed | M25: api-e2e-tests.json: 'Authentication and session security (AP-01..04, BO-01) ends the session on logout' passed (2 Oct 2026 14:55 UTC); test-reruns.json: passed (2 Oct 2026 22:00 UTC) | N25: 2 Oct 2026 22:00 UTC | O25: iorta QA (Vitest e2e, iift_test database)
A26: CS-0025 | B26: TS-03 | C26: TC-014 | D26: AUT | E26: SEC-07 (OWASP A07): A session cookie cannot be reused after logout (server-side revocation) | F26: Security tester | G26: 1. Run `node tools/security/security-checks.mjs` against a fresh non-production instance with demonstration data 2. Read the result of SEC-07 | H26: Demonstration users and records; crafted payloads as described in the script | I26: Old cookie rejected (401) after logout | J26: Security | K26: Automated – tools/security/security-checks.mjs | L26: Passed | M26: security-checks.json: SEC-07 PASS (2 Oct 2026 14:57 UTC); evidence summarised in the Security Assessment Report | N26: 2 Oct 2026 14:57 UTC | O26: iorta QA (security-checks.mjs)
A27: CS-0026 | B27: TS-03 | C27: TC-015 | D27: AUT | E27: Signing in again ends the earlier session (single active session) | F27: ag-000003 | G27: 1. Sign in twice as ag-000003 2. GET /api/v1/auth/me with the first cookie | H27: security.session.single_active = true | I27: The first session receives 401 NOT_AUTHENTICATED after the second sign-in | J27: API | K27: Executed – API run (tools/testing/api-test-run.mjs) | L27: Passed | M27: api-test-run.json EX-008: Two sign-ins as ag-000003, then GET /api/v1/auth/me with the first cookie → 401 NOT_AUTHENTICATED – Please sign in | N27: 2 Oct 2026 22:12 UTC | O27: iorta TechNXT QA (API run)
A28: CS-0027 | B28: TS-03 | C28: TC-015 | D28: AUT | E28: State-changing request without the CSRF token is refused | F28: ag-000001 | G28: 1. POST /api/v1/common/notifications/read-all without x-csrf-token 2. Repeat with a forged token 3. Repeat with the session's token | H28: Session of ag-000001 | I28: HTTP 403 CSRF_TOKEN_INVALID without token and with a forged token; 204 with the session token | J28: API | K28: Executed – API run (tools/testing/api-test-run.mjs) | L28: Passed | M28: api-test-run.json EX-003: POST /api/v1/common/notifications/read-all (no token; forged token; session token) → 403 CSRF_TOKEN_INVALID – Security token missing or invalid. Refresh the page. | 403 CSRF_TOKEN_INVALID – Security token missing or invalid. Refresh the page. | 204 | N28: 2 Oct 2026 22:12 UTC | O28: iorta TechNXT QA (API run)
... A31: CS-0030 | B31: TS-03 | C31: TC-015 | D31: AUT | E31: SEC-15 (OWASP A01): State-changing requests require the session’s own CSRF token | F31: Security tester | G31: 1. Run `node tools/security/security-checks.mjs` against a fresh non-production instance with demonstration data 2. Read the result of SEC-15 | H31: Demonstration users and records; crafted payloads as described in the script | I31: 403 without the session's own CSRF token | J31: Security | K31: Automated – tools/security/security-checks.mjs | L31: Passed | M31: security-checks.json: SEC-15 PASS (2 Oct 2026 14:57 UTC); evidence summarised in the Security Assessment Report | N31: 2 Oct 2026 14:57 UTC | O31: iorta QA (security-checks.mjs)
A32: CS-0031 | B32: TS-03 | C32: TC-016 | D32: AUT | E32: Idle timeout ends the session after 15 minutes | F32: Any user | G32: 1. Sign in 2. Leave the browser idle for 16 minutes 3. Click any navigation | H32: security.session.idle_minutes = 15 | I32: Redirected to sign-in with 'session ended'; API answers 401 | J32: UI | K32: Not automated | L32: Not executed | M32: Not executed – time-based; scheduled for SIT regression (Playwright) in week 16
A33: CS-0032 | B33: TS-03 | C33: TC-016 | D33: AUT | E33: Absolute timeout ends the session after 8 hours | F33: Any user | G33: 1. Keep a session active with periodic requests for 8 h | H33: security.session.absolute_hours = 8 | I33: Session ends at 8 h regardless of activity | J33: SIT | K33: Not automated | L33: Not executed | M33: Not executed – time-based; SIT soak run
A34: CS-0033 | B34: TS-04 | C34: TC-017 | D34: AUT | E34: Lockout after five failed attempts (suite) | F34: finance, support, ag-000001..3, admin | G34: 1. Run `npm run test:e2e -w apps/api` (rebuilds the iift_test database from the migrations and seeds) 2. 5 wrong passwords for support 3. Correct password | H34: support | I34: Sixth attempt 401 ACCOUNT_LOCKED | J34: E2E | K34: Automated – apps/api/test/auth.e2e-spec.ts › locks the account after the configured number of failed attempts | L34: Passed | M34: api-e2e-tests.json: 'Authentication and session security (AP-01..04, BO-01) locks the account after the configured number of failed attempts' passed (2 Oct 2026 14:55 UTC); test-reruns.json: passed (2 Oct 2026 22:00 UTC) | N34: 2 Oct 2026 22:00 UTC | O34: iorta QA (Vitest e2e, iift_test database)
A35: CS-0034 | B35: TS-04 | C35: TC-018 | D35: AUT | E35: Account lockout after the configured failed attempts; administrator unlock | F35: qa user, manager | G35: 1. Wait 61 s for the sign-in rate limit 2. POST /api/v1/auth/login 5× with a wrong password for the user of EX-110 3. POST with the temporary password 4. As manager POST users/{id}/unlock 5. Sign in; GET /api/v1/backoffice/users 6. Disable the test user | H35: security.lockout.max_attempts = 5 | I35: 5 wrong passwords → 401; the correct password then → 401 ACCOUNT_LOCKED; unlock → 200; sign-in → 200 and back-office access refused with 403 PASSWORD_CHANGE_REQUIRED until the temporary password is changed | J35: API | K35: Executed – API run (tools/testing/api-test-run.mjs) | L35: Passed | M35: api-test-run.json EX-133: POST /api/v1/auth/login ×6; POST /api/v1/backoffice/users/{id}/unlock; sign-in; GET /api/v1/backoffice/users; disable the test user → 401,401,401,401,401 | 401 ACCOUNT_LOCKED – Your account is temporarily locked after repeated failed sign-in attempts. Try again later or contact the administrator. | unlock 200 | sign-in 200 mustChangePassword=true | 403 PASSWORD_CHANGE_REQUIRED – You must change your password before continuing | disabled 200 | N35: 2 Oct 2026 22:14 UTC | O35: iorta TechNXT QA (API run)
A36: CS-0035 | B36: TS-05 | C36: TC-019 | D36: AUT | E36: LDAP filter escaping | F36: Anonymous | G36: 1. Sign in with user name 'admin)(objectClass=*' | H36: LDAP characters | I36: 401; directory query not altered | J36: Security | K36: Not automated | L36: Not executed | M36: Not executed in this run; covered by automated check SEC-19
A37: CS-0036 | B37: TS-05 | C37: TC-019 | D37: AUT | E37: SEC-19 (OWASP A03): LDAP filter characters in usernames do not alter directory queries | F37: Security tester | G37: 1. Run `node tools/security/security-checks.mjs` against a fresh non-production instance with demonstration data 2. Read the result of SEC-19 | H37: Demonstration users and records; crafted payloads as described in the script | I37: 401; LDAP filter characters escaped | J37: Security | K37: Automated – tools/security/security-checks.mjs | L37: Passed | M37: security-checks.json: SEC-19 PASS (2 Oct 2026 14:57 UTC); evidence summarised in the Security Assessment Report | N37: 2 Oct 2026 14:57 UTC | O37: iorta QA (security-checks.mjs)
A38: CS-0037 | B38: TS-05 | C38: TC-020 | D38: AUT | E38: Back-office sign-on through IIFT Active Directory | F38: IIFT staff | G38: 1. Configure LDAP_URL and bind account 2. Sign in with a directory user 3. Attempt a reset | H38: IITH AD test OU | I38: Directory user signs in; reset refused with DIRECTORY_ACCOUNT | J38: SIT | K38: Not automated | L38: Not executed | M38: Not executed – requires IIFT environment (LDAP endpoint)
A39: CS-0038 | B39: TS-06 | C39: TC-021 | D39: ACC | E39: Unauthenticated request refused (suite) | F39: ag-000001..3, finance, ops.maker, manager, system | G39: 1. Run `npm run test:e2e -w apps/api` (rebuilds the iift_test database from the migrations and seeds) 2. GET /portal/policies without a session | H39: None | I39: 401 NOT_AUTHENTICATED | J39: E2E | K39: Automated – apps/api/test/access-control.e2e-spec.ts › rejects unauthenticated requests | L39: Passed | M39: api-e2e-tests.json: 'Access control and input handling (AP-59, BO-02, COM-02, NFR-10/14/15) rejects unauthenticated requests' passed (2 Oct 2026 14:55 UTC); test-reruns.json: passed (2 Oct 2026 22:00 UTC) | N39: 2 Oct 2026 22:00 UTC | O39: iorta QA (Vitest e2e, iift_test database)
A40: CS-0039 | B40: TS-06 | C40: TC-021 | D40: ACC | E40: SEC-09 (OWASP A01): Protected endpoints require a session | F40: Security tester | G40: 1. Run `node tools/security/security-checks.mjs` against a fresh non-production instance with demonstration data 2. Read the result of SEC-09 | H40: Demonstration users and records; crafted payloads as described in the script | I40: 401 without a session | J40: Security | K40: Automated – tools/security/security-checks.mjs | L40: Passed | M40: security-checks.json: SEC-09 PASS (2 Oct 2026 14:57 UTC); evidence summarised in the Security Assessment Report | N40: 2 Oct 2026 14:57 UTC | O40: iorta QA (security-checks.mjs)
A41: CS-0040 | B41: TS-06 | C41: TC-022 | D41: ACC | E41: Portal user cannot call back-office routes and vice versa | F41: ag-000001, finance | G41: 1. As ag-000001 GET /api/v1/backoffice/agents 2. As finance GET /api/v1/portal/policies | H41: Portal and back-office sessions | I41: HTTP 403 WRONG_AUDIENCE in both directions | J41: API | K41: Executed – API run (tools/testing/api-test-run.mjs) | L41: Passed | M41: api-test-run.json EX-004: GET /api/v1/backoffice/agents as agent; GET /api/v1/portal/policies as finance → 403 WRONG_AUDIENCE – This function is not available to your account type | 403 WRONG_AUDIENCE – This function is not available to your account type | N41: 2 Oct 2026 22:12 UTC | O41: iorta TechNXT QA (API run)
A42: CS-0041 | B42: TS-06 | C42: TC-022 | D42: ACC | E42: Audience separation (suite) | F42: ag-000001..3, finance, ops.maker, manager, system | G42: 1. Run `npm run test:e2e -w apps/api` (rebuilds the iift_test database from the migrations and seeds) 2. Agent calls back-office; finance calls portal | H42: ag-000001, finance | I42: 403 WRONG_AUDIENCE both ways | J42: E2E | K42: Automated – apps/api/test/access-control.e2e-spec.ts › keeps portal users out of the back-office API and vice versa | L42: Passed | M42: api-e2e-tests.json: 'Access control and input handling (AP-59, BO-02, COM-02, NFR-10/14/15) keeps portal users out of the back-office API and vice versa' passed (2 Oct 2026 14:55 UTC); test-reruns.json: passed (2 Oct 2026 22:00 UTC) | N42: 2 Oct 2026 22:00 UTC | O42: iorta QA (Vitest e2e, iift_test database)
...

Sheet Defects
A1: ID | B1: Title | C1: Severity | D1: Priority | E1: Area | F1: Description | G1: Found by | H1: Status | I1: Cases
A2: DEF-001 | B2: End-to-end claim test uses the UTC calendar day instead of the Brunei business day | C2: Low | D2: Medium | E2: Test assets (apps/api/test/operations.e2e-spec.ts) | F2: The test 'accepts claim notifications only within the period of cover' notifies a claim dated today() in UTC. Policies seeded after 16:00 UTC start on the next Brunei day, so the claim is refused with CLAIM_NOT_VALID and the test fails when the suite runs between 16:00 and 24:00 UTC. The application behaves correctly (the same case passed in the API run with the Brunei date, EX-067). The evidence run at 14:50 UTC passed; the re-run at 22:00 UTC failed. | G2: iorta QA, re-run of the end-to-end suite on 2 October 2026 | H2: Open – fix in test code (use the business-day helper); no product change | I2: CS-0214
A3: DEF-002 | B3: Administrator password reset re-activates a disabled account | C3: Medium | D3: High | E3: User administration (apps/api/src/modules/access/users.service.ts, resetPassword) | F3: Resetting the password of a user whose status is DISABLED sets the status back to ACTIVE, and the user can sign in with the temporary password (EX-134: reset 200, sign-in 200). The audit trail records USER_PASSWORD_RESET only, not a re-activation. An administrator who resets a password should not silently re-enable an account that another administrator disabled; re-activation should be an explicit, separately audited status change (BO-03, NFR-10). The unlock function behaves correctly (it refuses disabled accounts). | G3: iorta QA, API run of 2 October 2026 | H3: Open – fix proposed: keep the status on reset and audit any re-activation; to be confirmed with IIFT | I3: CS-0268

Sheet Traceability
A1: RFP ID | B1: Area | C1: Requirement | D1: Scenarios | E1: Cases | F1: Executed | G1: Passed | H1: Failed | I1: Case IDs | J1: Coverage
A2: AP-01 | B2: Authentication | C2: Secure login | D2: TS-01 | E2: 9 | F2: 8 | G2: 8 | H2: 0 | I2: CS-0001–CS-0009 | J2: Partly executed – passed
A3: AP-02 | B3: Authentication | C3: Password management | D3: TS-02 | E3: 10 | F3: 9 | G3: 9 | H3: 0 | I3: CS-0010–CS-0019 | J3: Partly executed – passed
A4: AP-03 | B4: Authentication | C4: Session management | D4: TS-03 | E4: 13 | F4: 11 | G4: 11 | H4: 0 | I4: CS-0020–CS-0032 | J4: Partly executed – passed
A5: AP-04 | B5: Authentication | C5: Account lockout | D5: TS-04 | E5: 2 | F5: 2 | G5: 2 | H5: 0 | I5: CS-0033–CS-0034 | J5: Executed – passed
A6: AP-05 | B6: Agent/Banca profile | C6: View agent/banca profile | D6: TS-09 | E6: 4 | F6: 4 | G6: 4 | H6: 0 | I6: CS-0061–CS-0064 | J6: Executed – passed
A7: AP-06 | B7: Agent/Banca profile | C7: Maintain profile (subject to approval) | D7: TS-09 | E7: 4 | F7: 4 | G7: 4 | H7: 0 | I7: CS-0061–CS-0064 | J7: Executed – passed
A8: AP-07 | B8: Agent/Banca management | C8: Agent/banca registration | D8: TS-08 | E8: 8 | F8: 8 | G8: 8 | H8: 0 | I8: CS-0053–CS-0060 | J8: Executed – passed
A9: AP-08 | B9: Agent/Banca management | C9: Agent ID generation | D9: TS-08 | E9: 8 | F9: 8 | G9: 8 | H9: 0 | I9: CS-0053–CS-0060 | J9: Executed – passed
A10: AP-09 | B10: Agent/Banca management | C10: Main/sub-agent relationships | D10: TS-07, TS-09 | E10: 10 | F10: 10 | G10: 10 | H10: 0 | I10: CS-0047–CS-0052, CS-0061–CS-0064 | J10: Executed – passed
A11: AP-10 | B11: Agent/Banca management | C11: Agency/banca information | D11: TS-09 | E11: 4 | F11: 4 | G11: 4 | H11: 0 | I11: CS-0061–CS-0064 | J11: Executed – passed
A12: AP-11 | B12: Agent/Banca management | C12: Cross-agency participant sharing | D12: TS-07, TS-12 | E12: 11 | F12: 11 | G12: 11 | H12: 0 | I12: CS-0047–CS-0052, CS-0077–CS-0081 | J12: Executed – passed
A13: AP-12 | B13: Agent/Banca management | C13: Agency-wide participant visibility | D13: TS-07, TS-12 | E13: 11 | F13: 11 | G13: 11 | H13: 0 | I13: CS-0047–CS-0052, CS-0077–CS-0081 | J13: Executed – passed
... A140: NFR-19 | B140: Disaster recovery | C140: DR testing | D140: TS-61 | E140: 2 | F140: 0 | G140: 0 | H140: 0 | I140: CS-0326–CS-0327 | J140: Cases defined, not executed
A141: NFR-20 | B141: Maintainability | C141: Modular architecture | E141: 0 | F141: 0 | G141: 0 | H141: 0 | J141: Verified by review of the Solution Architecture (modular monolith); not a test case
A142: NFR-21 | B142: Maintainability | C142: Documentation | E142: 0 | F142: 0 | G142: 0 | H142: 0 | J142: Verified by the document pack and its rebuild from source; not a test case
A143: NFR-22 | B143: Usability | C143: User interface | D143: TS-62, TS-70 | E143: 94 | F143: 92 | G143: 92 | H143: 0 | I143: CS-0328–CS-0330, CS-0348–CS-0438 | J143: Partly executed – passed
A144: NFR-23 | B144: Usability | C144: Browser compatibility | D144: TS-62 | E144: 3 | F144: 1 | G144: 1 | H144: 0 | I144: CS-0328–CS-0330 | J144: Partly executed – passed
A145: NFR-24 | B145: Accessibility | C145: Accessibility | D145: TS-62 | E145: 3 | F145: 1 | G145: 1 | H145: 0 | I145: CS-0328–CS-0330 | J145: Partly executed – passed
A146: NFR-25 | B146: Compatibility | C146: API standards | D146: TS-64 | E146: 1 | F146: 0 | G146: 0 | H146: 0 | I146: CS-0333 | J146: Cases defined, not executed
A147: NFR-26 | B147: Monitoring | C147: System monitoring | D147: TS-60 | E147: 2 | F147: 0 | G147: 0 | H147: 0 | I147: CS-0324–CS-0325 | J147: Cases defined, not executed
A148: NFR-27 | B148: Monitoring | C148: Alerting | D148: TS-53, TS-60 | E148: 5 | F148: 2 | G148: 2 | H148: 0 | I148: CS-0290–CS-0292, CS-0324–CS-0325 | J148: Partly executed – passed
A149: NFR-28 | B149: Logging | C149: Centralised logs | D149: TS-60 | E149: 2 | F149: 0 | G149: 0 | H149: 0 | I149: CS-0324–CS-0325 | J149: Cases defined, not executed
A150: NFR-29 | B150: Data | C150: Data retention | D150: TS-65 | E150: 1 | F150: 0 | G150: 0 | H150: 0 | I150: CS-0334 | J150: Cases defined, not executed
A151: NFR-30 | B151: Data | C151: Data quality | D151: TS-11, TS-38, TS-56 | E151: 31 | F151: 29 | G151: 29 | H151: 0 | I151: CS-0071–CS-0076, CS-0217–CS-0228, CS-0304–CS-0316 | J151: Partly executed – passed
A152: DEL-09 | B152: Integration | C152: Interface specification | D152: TS-64 | E152: 1 | F152: 0 | G152: 0 | H152: 0 | I152: CS-0333 | J152: Cases defined, not executed
A153: DEL-12 | B153: Testing | C153: Test strategy | E153: 0 | F153: 0 | G153: 0 | H153: 0 | J153: This Test Strategy
A154: DEL-13 | B154: Testing | C154: SIT test cases | E154: 0 | F154: 0 | G154: 0 | H154: 0 | J154: This workbook (Scenarios, Conditions, Cases)
A155: DEL-14 | B155: Testing | C155: SIT results | E155: 0 | F155: 0 | G155: 0 | H155: 0 | J155: Execution log and evidence files of this workbook; the SIT results report follows SIT
A156: DEL-15 | B156: Testing | C156: UAT test cases | D156: TS-67 | E156: 1 | F156: 0 | G156: 0 | H156: 0 | I156: CS-0336 | J156: Cases defined, not executed
A157: DEL-16 | B157: Testing | C157: UAT results | D157: TS-67 | E157: 1 | F157: 0 | G157: 0 | H157: 0 | I157: CS-0336 | J157: Cases defined, not executed
A158: DEL-17 | B158: Security | C158: Security assessment (VAPT) | D158: TS-57 | E158: 3 | F158: 0 | G158: 0 | H158: 0 | I158: CS-0317–CS-0319 | J158: Cases defined, not executed
A159: DEL-18 | B159: Performance | C159: Performance test report | D159: TS-59 | E159: 3 | F159: 0 | G159: 0 | H159: 0 | I159: CS-0321–CS-0323 | J159: Cases defined, not executed
A160: DEL-19 | B160: Migration | C160: Data migration plan | D160: TS-66 | E160: 1 | F160: 0 | G160: 0 | H160: 0 | I160: CS-0335 | J160: Cases defined, not executed
A161: DEL-20 | B161: Deployment | C161: Deployment plan | D161: TS-68 | E161: 1 | F161: 0 | G161: 0 | H161: 0 | I161: CS-0337 | J161: Cases defined, not executed
A162: DEL-21 | B162: Deployment | C162: Go-live checklist | D162: TS-68 | E162: 1 | F162: 0 | G162: 0 | H162: 0 | I162: CS-0337 | J162: Cases defined, not executed
A163: MNT-15 | B163: Technology | C163: Browser compatibility | D163: TS-62 | E163: 3 | F163: 1 | G163: 1 | H163: 0 | I163: CS-0328–CS-0330 | J163: Partly executed – passed
